Workbook
Name LST_CASO: TABLAS!$B$72:$B$79
Name LST_TIPO: TABLAS!$C$72:$C$73
Name LST_BORDE: TABLAS!$D$72:$D$73
Name LST_COLADO: TABLAS!$E$72:$E$73
Name LST_SINO: TABLAS!$F$72:$F$73
Name LST_AGR: TABLAS!$G$72:$G$73
Name LST_DEST: DATOS!$B$46:$B$55
Name LST_MALLA: TABLAS!$B$63:$B$66
Name LST_TAB: TABLAS!$C$86:$C$165

Sheet INSTRUCCIONES
B1: LOSAS NERVADAS Y MACIZAS — NTC 2023 (CDMX) · HOJA GENERAL
B2: Diseño por flexión y cortante de tableros de losa con el método de coeficientes de la NTC-Concreto 2023 (Tabla 3.4.2.1), para cualquier proyecto. Sale de la hoja auditada de Casa Rocha: mismas ecuaciones, mismas citas («NTC-Concreto 2023 (CDMX) 6.7.8.1.4, p. 187»).
B4: 1. QUÉ HACE
B5: • NERVADAS: hasta 40 tableros de losa nervada (encasetonada). Por tablero: caso de la tabla, coeficientes interpolados en m = a1/a2, momentos por nervadura en las dos direcciones, As, número y cantidad de varillas (sube de número si no cabe), M_R, ε_t ≥ 0.005, cortante con V_cR (×1.1 sólo si cumple 6.7.8.1.4), hileras de casetones a macizar, espesor mínimo contra h_eq, bastones y estado.
B6: • MACIZAS: hasta 40 tableros de losa maciza, por franja de 1 m: los mismos pasos, con As mínima 0.0018·b·h, varilla y separación («No. 3 @ 20 cm»), cortante de losa y h mínimo.
B7: • VOLADOS (en las dos hojas): momento y cortante en el paño del apoyo con la carga lineal en la orilla y el peso de los macizos (nervadas), y acero superior que entra al tablero de respaldo. En nervadas, si el volado lleva nervaduras más anchas, cuántas hileras del respaldo siguen con ellas (decisión D10 de Casa Rocha).
B8: • DETALLE: memoria paso a paso del tablero que escojas (fórmula y referencia de cada paso), lista para imprimir.
B9: • CROQUIS: planta, corte y alzado del tablero escogido, a escala, que se redibujan solos al cambiar de tablero.
B11: 2. ALCANCE Y LÍMITES — LÉELO
B12: • Método de coeficientes (NTC-Concreto 2023, 3.4.2 y Tabla 3.4.2.1) para tableros rectangulares APOYADOS EN SU PERÍMETRO sobre muros o trabes. Sólo está transcrito el CASO I (losa colada monolíticamente con sus apoyos); un tablero marcado como caso II sale FUERA DE ALCANCE.
B13: • Condición 3.4.2.1 c): los momentos negativos de tableros vecinos en un borde común no deben diferir más de 50 % del menor. La hoja NO conoce a los vecinos: captura el M⁻ del vecino (columna opcional) y la hoja arma con el mayor y te avisa si difieren más de 50 %. Si es así, distribuye el desequilibrio (3.4.3.1) o confirma con un modelo.
B14: • Condición 3.4.2.1 d) (W_m ≤ 2.5·CM aprox.) y las demás de 3.4.2.1: revísalas tú; la hoja supone tableros rectangulares de cargas uniformes. Para tableros irregulares usa un rectángulo representativo.
... B19: 3. COLORES
B20: Celda de captura | C20: Amarillo con número azul: aquí se escribe. Todo lo demás es fórmula.
B21: Fórmula | C21: Negro: calculado. No se escribe encima.
B22: Resultado clave | C22: Azul pálido: resultado que importa (w_u, Mu/M_R, armado).
B23: CUMPLE | C23: Verde: pasa.
B24: MACIZAR 1 hilera(s) | C24: Ámbar: pasa con una acción (macizar, calcular flecha).
B25: NO CUMPLE | C25: Rojo: no pasa, faltan datos o está fuera de alcance.
B27: 4. CÓMO SE USA, PASO A PASO
B28: 1) DATOS: captura materiales, factores, recubrimientos, la sección nervada (a_c, h_c, b_w, t), la malla y los valores por omisión de macizas. Revisa la lista de destinos (cargas vivas).
B29: 2) NERVADAS o MACIZAS: un renglón por tablero. Borra o sobrescribe los renglones «EJEMPLO». Captura nombre, tipo (PERIMETRAL o VOLADO), destino, a_x y a_y a ejes, y cada borde como CONTINUO (sigue losa del otro lado) o DISCONTINUO (orilla, hueco o losa que no sigue). El caso de la tabla sale solo (puedes forzarlo).
B30: 3) Captura la sobrecarga muerta SCM (acabados, rellenos, plafón, muros divisorios repartidos). La carga viva sale del destino; si quieres otra, escríbela en «CV propia».
B31: 4) Volados: carga lineal en la orilla (barandal, pretil) y claro del tablero de respaldo L_b. En nervadas puedes darle al volado otra b_w (20 cm suele hacer falta): la columna «Respaldo del volado» dice cuántas hileras del tablero de respaldo siguen con esa nervadura; anótalas también en el renglón de ese tablero.
B32: 5) Lee ESTADO y NOTA. Si dice NO CUMPLE, la nota y las columnas en rojo dicen qué falla (flexión, no caben, ε_t, cortante, peralte).
B33: 6) DETALLE: escoge el tablero en la celda amarilla y obtén la memoria paso a paso. CROQUIS dibuja ese mismo tablero.
B34: 7) Imprime DETALLE y CROQUIS (ya tienen área de impresión) y pasa a planos el armado de la columna «ARMADO».
B36: 5. REVISIONES QUE HACE CADA RENGLÓN
B37: • Flexión en los cuatro lechos (inferior y superior, claro corto y largo): Mu ≤ M_R, As ≥ mínima, p ≤ p_max y ε_t ≥ 0.005 (F_R = 0.9) — 3.8.2, 6.3.5, 6.7.6.1.
B38: • Que las varillas quepan con la separación libre mínima (nervadas) o que la separación no pase de la máxima (macizas) — 14.2.1.
B39: • Cortante a d del paño: V_u ≤ V_cR (ec. 5.5.3.2.1); en nervadas, hileras de casetones a macizar si no alcanza; ×1.1 sólo si cumple 6.7.8.1.4.
... B46: RESPONSABILIDAD: la hoja es una herramienta de cálculo; el Director Responsable de Obra / Corresponsable revisa datos, hipótesis y resultados. Los renglones EJEMPLO vienen de la hoja de Casa Rocha (nervadas) y de tableros típicos (macizas) sólo para mostrar cómo se llena.

Sheet DATOS
B1: DATOS GENERALES — LOSAS NERVADAS Y MACIZAS, NTC 2023 (CDMX)
B2: Datos que valen para todo el libro. Lo de cada tablero va en NERVADAS y MACIZAS. Cada número capturado dice de dónde sale (columna «Referencia»); lo que es criterio de esta hoja y no de la norma se dice así.
B4: CÓMO SE USA: sólo se tocan las celdas AMARILLAS con número AZUL. Lo demás está calculado y se rompe si lo escribes encima. Los valores que trae la hoja son un punto de partida (los de la hoja auditada de Casa Rocha): cámbialos por los de tu proyecto.
B6: 0. PROYECTO
B7: Concepto | C7: Valor | D7: Unidad | E7: Cómo se calcula / de dónde sale | F7: Referencia
B8: Proyecto | C8: NOMBRE DEL PROYECTO | D8: — | E8: CAPTURA. Sale en DETALLE y en CROQUIS. | F8: —
B9: Elaboró / revisó | C9: — | D9: — | E9: CAPTURA. | F9: —
B11: 1. MATERIALES
B12: Concepto | C12: Valor | D12: Unidad | E12: Cómo se calcula / de dónde sale | F12: Referencia
B13: f'c — resistencia del concreto | C13: 250 | D13: kg/cm² | E13: CAPTURA. Clase 1A (250 ≤ f'c < 400). Mínimo para exposición A1, A2 y B1. | F13: NTC-Concreto 2023 (CDMX) 2.2.2 a), p. 30 · Tabla 2.2.6.3, p. 33 · 4.4.1.1 y 4.5.2 a), p. 78
B14: fy — fluencia de la varilla corrugada | C14: 4200 | D14: kg/cm² | E14: CAPTURA. Grado 42, NMX-B-506. | F14: NTC-Concreto 2023 (CDMX) Tabla 2.4.2.1.2.a, p. 43
B15: fy de la malla electrosoldada | C15: 5000 | D15: kg/cm² | E15: CAPTURA. Alambre de malla NMX-B-290. Sólo se usa en la capa de compresión. | F15: NTC-Concreto 2023 (CDMX) 2.4.2.1.6 y 2.4.2.1.7, p. 44
B16: γc — peso volumétrico del concreto reforzado | C16: 2.4 | D16: t/m³ | E16: CAPTURA. Valor máximo probable. Si tu modelo usa otro (Casa Rocha: 2.44), pon el del modelo. | F16: NTC-Criterios y Acciones 2023 (CDMX) 5.1.1.2, p. 9
B17: γ del casetón (poliestireno) | C17: 0.015 | D17: t/m³ | E17: CAPTURA. Poliestireno expandido de 15 kg/m³. Si el casetón es recuperable (de plástico), pon 0. | F17: Criterio de esta hoja (dato del fabricante)
B18: Agregado grueso del concreto | C18: CALIZO | D18: — | E18: SELECTOR. Cambia Ec: calizo 14 000·√f'c, basáltico 11 000·√f'c. Especificarlo en planos. | F18: NTC-Concreto 2023 (CDMX) Tabla 2.2.1, p. 31 · 2.2.8.4, p. 34
B19: Ec — módulo de elasticidad | C19: =IF(DATOS!$C$18="BASALTO",11000,14000)*SQRT(DATOS!$C$13) -> 221359.44 | D19: kg/cm² | E19: CALCULADA = 14 000·√f'c (calizo) u 11 000·√f'c (basalto). Informativa (flechas). | F19: NTC-Concreto 2023 (CDMX) Tabla 2.2.1, p. 31
B20: Es — módulo de elasticidad del acero | C20: 2000000 | D20: kg/cm² | E20: CAPTURA. | F20: NTC-Concreto 2023 (CDMX) 2.4.2.2.2, p. 45
B21: f''c — esfuerzo del bloque equivalente | C21: =0.85*DATOS!$C$13 -> 212.5 | D21: kg/cm² | E21: CALCULADA = 0.85·f'c. | F21: NTC-Concreto 2023 (CDMX) 3.6.1 e), p. 68
B22: β1 — profundidad del bloque | C22: =IF(DATOS!$C$13<=300,0.85,MAX(0.65,1.05-DATOS!$C$13/1400)) -> 0.85 | D22: — | E22: CALCULADA. 0.85 hasta f'c = 300 kg/cm². | F22: NTC-Concreto 2023 (CDMX) ec. 3.6.1, p. 68
B24: 2. FACTORES DE CARGA Y DE RESISTENCIA
B25: Concepto | C25: Valor | D25: Unidad | E25: Cómo se calcula / de dónde sale | F25: Referencia
B26: FC_CM — factor de carga muerta | C26: 1.3 | D26: — | E26: CAPTURA. Grupo B (Grupo A: 1.5). | F26: NTC-Criterios y Acciones 2023 (CDMX) 3.4.1 a), p. 7 (combinación 2.3.1 a), p. 5)
B27: FC_CV — factor de carga viva | C27: 1.5 | D27: — | E27: CAPTURA. Grupo B (Grupo A: 1.7). | F27: NTC-Criterios y Acciones 2023 (CDMX) 3.4.1 a), p. 7
B28: FC_acc — factor en combinaciones con acciones accidentales | C28: 1.1 | D28: — | E28: CAPTURA. Combinación de granizo en azotea: 1.1·(CM + W_g), sin carga viva. | F28: NTC-Criterios y Acciones 2023 (CDMX) 3.4.1 b), p. 7 · 7.3.1.3, p. 17
B29: F_R — flexión | C29: 0.9 | D29: — | E29: CAPTURA. Vale si la sección es controlada por tensión (ε_t ≥ 0.005); la hoja limita el acero para garantizarlo (p_max). | F29: NTC-Concreto 2023 (CDMX) Tabla 3.8.2.1 a) y Tabla 3.8.2.2, p. 70 · 3.8.2.4, p. 71 · 6.7.3.3.1, p. 169
B30: F_R — cortante | C30: 0.75 | D30: — | E30: CAPTURA. | F30: NTC-Concreto 2023 (CDMX) Tabla 3.8.2.1 b), p. 70
B31: Fracción de la cuantía balanceada que se permite | C31: 0.9 | D31: — | E31: CAPTURA. Tope de ductilidad baja; en la práctica manda antes ε_t ≥ 0.005. | F31: NTC-Concreto 2023 (CDMX) 6.3.5.2.1, p. 122
B32: Incremento de V_cR en losas encasetonadas | C32: 1.1 | D32: — | E32: CAPTURA. Sólo en tableros que cumplen 6.7.8.1.4 (claro corto ≥ 6·a_c); en los demás vale 1.0. No aplica a losas macizas. | F32: NTC-Concreto 2023 (CDMX) 6.7.8.1.5, p. 187 · 6.7.8.1.9, p. 188
B33: Incremento de cortante con bordes continuos y discontinuos | C33: 1.15 | D33: — | E33: CAPTURA. De la fórmula de cortante de losas apoyadas en su perímetro de la NTC 2017, que la 2023 ya no trae; se conserva como «método reconocido». | F33: NTC-Concreto 2023 (CDMX) 3.4.1.1, p. 64 (métodos reconocidos) · NTC-Concreto 2017
B35: 3. CARGA MUERTA ADICIONAL Y GRANIZO
B36: Concepto | C36: Valor | D36: Unidad | E36: Cómo se calcula / de dónde sale | F36: Referencia
B37: Incremento del peso propio por losa colada en el lugar | C37: 20 | D37: kg/m² | E37: CAPTURA. Se suma al peso propio de todos los tableros. | F37: NTC-Criterios y Acciones 2023 (CDMX) 5.1.2.1, p. 9
B38: Incremento por capa de mortero sobre la losa (pegapiso, firme o entortado) | C38: 20 | D38: kg/m² | E38: CAPTURA. Si tu sobrecarga ya trae estos 20 kg/m², pon 0 para no contarlos dos veces. No se aplica donde la carga muerta es favorable. | F38: NTC-Criterios y Acciones 2023 (CDMX) 5.1.2.1 y 5.1.2.2, p. 9
B39: H_s — altura de granizo | C39: 0.125 | D39: m | E39: CAPTURA. Azotea con pendiente < 5°, Grupo B. | F39: NTC-Criterios y Acciones 2023 (CDMX) Tabla 7.3.2.2, p. 18
B40: C_s — coeficiente de forma | C40: 1 | D40: — | E40: CAPTURA. | F40: NTC-Criterios y Acciones 2023 (CDMX) Tabla 7.3.2.3, p. 18
B41: W_g — granizo en azotea = 900·H_s·C_s | C41: =900*DATOS!$C$39*DATOS!$C$40 -> 112.5 | D41: kg/m² | E41: CALCULADA. Va con FC = 1.1 y sin carga viva; la hoja toma el mayor de esa combinación y la gravitacional en los destinos marcados como azotea. | F41: NTC-Criterios y Acciones 2023 (CDMX) ec. 7.3.2.1, p. 17 · 3.4.1 b), p. 7
B43: 4. CARGAS VIVAS UNITARIAS (lista de destinos)
B44: Los tableros escogen su destino de esta lista. W_m (máxima) es la de diseño por gravedad; W_a y W son informativas. «¿Azotea?» = SÍ activa la combinación con granizo. Los incisos a) y h) los cotejó la hoja de Casa Rocha; los demás son los de la misma tabla y hay que cotejarlos contra el texto oficial antes de usarlos. Puedes cambiar nombres y valores.
B45: Destino | C45: W_m | D45: ¿Azotea? (granizo) | E45: W_a / W (informativos) | F45: Referencia
B46: HABITACIÓN | C46: 190 | D46: NO | E46: 100 / 80 | F46: NTC-Criterios y Acciones 2023 (CDMX) Tabla 6.1.2.2 a), p. 11 (cotejado por la hoja de Casa Rocha)
...

Sheet NERVADAS
B1: NERVADAS — LOSA NERVADA (ENCASETONADA), UN RENGLÓN POR TABLERO · MÉTODO DE COEFICIENTES NTC-CONCRETO 2023, TABLA 3.4.2.1 (CASO I)
B2: Momentos por nervadura = coef·10⁻⁴·w_u·a1²·s. Abajo trabaja la sección T (patín b_f); arriba sólo la nervadura (b_w de cálculo). Toda nervadura lleva al menos 1 varilla corrida abajo y 1 arriba (6.7.6.1.3); arriba las demás son bastones. Sólo se captura lo AMARILLO; los renglones vacíos quedan en blanco. La memoria paso a paso de un tablero está en DETALLE y su dibujo en CROQUIS.
B3: ESTADO: «CUMPLE» = flexión, cupo, ε_t ≥ 0.005, cortante, peralte, capa y anclaje bien. «MACIZAR n hilera(s)» = quitar casetones junto a cada apoyo por cortante. «REVISAR: calcular flecha» = h_eq menor que el mínimo de la Tabla 6.7.3.1.2. «No cumple 6.7.8.1.4» (nota) = a_c > claro corto/6: losa apoyada en vigas (6.7.8.1.9). «FUERA de 3.4.2.1 c)» = el M⁻ del vecino capturado difiere más de 50 %.
B5: CAPTURA. Claros A EJES (del lado seguro; la tabla admite claros libres en el caso I). Borde CONTINUO = sigue losa del otro lado; DISCONTINUO = orilla, hueco o losa que no sigue. VOLADO: marca CONTINUO sólo el borde empotrado. CV propia, b_w propio y α_fm propio: vacío = el de DATOS. M⁻ del vecino: por nervadura, en el borde común; la hoja arma con el mayor. | U5: a1 = claro corto, a2 = largo (volado: a1 = largo perpendicular al borde empotrado). L_n = a − b_p (volado a − b_p/2) (NTC-Concreto 6.3.2.1, p. 117). Patín b_f = b_w + 2·mín(8t, a_c/2, L_n/8) ≤ s (Tabla 5.2.1.4.2, p. 89). 6.7.8: claro corto ≥ 6·a_c, a_c ≤ 80, b_w ≥ 10, h ≤ 3.5·b_w, t ≥ máx(a_c/13, 5) (6.7.8.1.2 a 6.7.8.1.4, p. 187); si NO: losa sobre vigas, r de viga, sin ×1.1 (6.7.8.1.9, p. 188). b_w − 2 cm si b_w < 20 sin 3.9.2 (3.9.1 e), p. 74). | AM5: PP = (h − a_c²·h_c/s²)·γc + casetón + 20 + 20 (NTC-Criterios 5.1.2.1, p. 9). CM = PP + SCM. w_u = máx(1.3·CM + 1.5·W_m; azotea: 1.1·(CM + W_g)) (NTC-Criterios 3.4.1 a) y b), p. 7; ec. 7.3.2.1, p. 17). | AR5: Se cuentan los bordes DISCONTINUOS; «corto» = borde de largo a1. Mismo criterio que la hoja de Casa Rocha; dos bordes opuestos discontinuos se toman como «extremo» (del lado seguro). Tabla 3.4.2.1, p. 65. | AV5: Interpolación lineal en m entre las columnas de la Tabla 3.4.2.1, caso I (TABLAS sección A). | BD5: M = coef·10⁻⁴·w_u·a1²·s, por nervadura (NTC-Concreto 3.4.2.1, p. 64). M⁻ = el mayor de borde continuo, discontinuo y el del vecino capturado. Volado: M⁻ = (w_u·L_n²/2 + 1.3·P·L_n)·s + M de los macizos (el PP promedio no cuenta el concreto que llena los casetones en el macizo de la punta, de ancho macizo de orilla + b_p/2, ni en el de la raíz: 1.3·γc·s·(vacío/m²)·ancho·brazo, como en la hoja de Casa Rocha). 3.4.2.1 c): M⁻ propio y del vecino no deben diferir más de 50 % (p. 64). | BK5: b = patín b_f. d con la varilla preferida para As; con la real para M_R. q = 1 − √(1 − 2Mu/(F_R·b·d²·f''c)), As = q·f''c·b·d/fy (ecs. 5.2.2.1.1.1, p. 89); As ≥ mín(p_min·b_w·d, 4/3·As) (6.3.5.1.3, p. 122); −1 = no alcanza o rebasa p_max. Varilla: la preferida o la siguiente que quepa (14.2.1, p. 347). ε_t = 0.003(d − c)/c ≥ 0.005 (Tabla 3.8.2.2, p. 70). | BS5: b = b_w de cálculo. d = h − máx(r, (t − 2Ø)/2) − 2·Ø malla − d_b/2 (la malla va al centro de la capa y la varilla pasa debajo), − 2 cm si d ≤ 20 cm sin la precaución de 3.9.2 (3.9.1 d), p. 74). 1 varilla corrida + bastones (6.7.6.1.3, p. 175). En volado el patín trabaja a tensión: As mín sobre 2·b_w. | CA5: Igual que el lecho inferior corto; el lecho del claro largo va encima del corto: d = h − r − d_b,corto − d_b/2. | CI5: Igual que el lecho superior corto; va debajo del lecho superior corto. | CQ5: V_u a d del paño = (L_n/2 − d)(0.95 − 0.5m)·w_u·s, ×1.15 con bordes continuos y discontinuos (método reconocido, 3.4.1.1, p. 64; 6.7.4.3.2, p. 172). Volado: (w_u(L_n − d) + 1.3P)·s. V_cR = F_R·2·λs·p^⅓·√f'c·b_w·d (ec. 5.5.3.2.1, p. 95), ×1.1 si cumple 6.7.8 (6.7.8.1.5, p. 187). Sin estribos (5.5.3.8.1, p. 97): lo que falte se cubre macizando hileras de casetones. | CU5: Tabla 6.7.3.1.2 (p. 168), α_fm > 2: L_n(0.8 + fy/14 000)/(36 + 9β) ≥ 9; 0.2–2: …/(36 + 5β(α_fm − 0.2)) ≥ 13; ≤ 0.2: Tabla 6.7.3.1.1 (L_n/30 ó /33, ≥ 13). +10 % con borde discontinuo sin viga (6.7.3.1.2.1). Se compara h_eq = ∛(12·I_T/s). Volado: L/8 contra h (Tabla 6.3.3.1.1, p. 120). Capa ≥ 6 cm si el claro es ≥ 6 m (6.8.3.1.2, p. 189). | DB5: Bastón desde el paño = punto de inflexión + máx(d, 12d_b, L_n/16), ≥ L_d (6.3.7.3.4, p. 127; 6.3.7.3.10.4, p. 129; Tabla 14.4.2.4, p. 353). Volado: entra al respaldo hasta M = 0 con 0.9·PP y sin CV. Anclaje en bordes discontinuos (dala de borde armada, D9 de Casa Rocha): 1.25·L_dh ≤ ancho − r_np y ≥ 15 cm (6.7.8.1.7, p. 188); L_dh del bastón (6.7.7.4.1.1 b), p. 179); gancho de 180° con alto 8·d_b ≤ peralte de la dala − 2·r_np (Tabla 14.3.1, p. 349). Respaldo de un volado con b_w propio: sus nervaduras anchas siguen en el respaldo hasta donde la nervadura de b_w de DATOS resiste el M⁻ (con 0.9·PP, sin CV) y el cortante del volado. | DK5: Sólo volados con b_w propio mayor que el de DATOS (decisión D10 de Casa Rocha). Del otro lado del apoyo el M⁻ del volado lo toman las nervaduras del tablero de respaldo: sus primeras hileras siguen con el b_w del volado (casetón s − b_w) hasta donde la nervadura normal (con r de viga, del lado seguro), con la varilla corrida del volado, resiste M(x) = M⁻(1 − x/L_b) − 0.9·PP·s·x(L_b − x)/2 (sin CV) y el cortante V(x) = M⁻/L_b + w_u·s·(L_b/2 − x). Las demás varillas del volado son bastones que terminan ahí, más máx(d, 12d_b) y no menos que L_d. La nervadura ancha se revisa a cortante junto al apoyo con el V_cR del volado (ec. 5.5.3.2.1, p. 95; 6.3.7.3.10.4, p. 129). | DU5: Armado por NERVADURA. Superior: 1 corrida + bastones a cada lado de los bordes continuos (y de los discontinuos si la columna lo pide). ESTADO junta flexión, cupo, ε_t, cortante, peralte, capa y anclaje.
B6: DATOS DEL TABLERO — CAPTURA (amarillo) | U6: GEOMETRÍA | AM6: CARGAS | AR6: CASO DE LA TABLA | AV6: COEFICIENTES ×10⁻⁴ (Tabla 3.4.2.1) | BD6: MOMENTOS POR NERVADURA | BK6: LECHO INFERIOR ‖ CLARO CORTO | BS6: LECHO SUPERIOR ‖ CLARO CORTO | CA6: LECHO INFERIOR ‖ CLARO LARGO | CI6: LECHO SUPERIOR ‖ CLARO LARGO | CQ6: CORTANTE | CU6: ESPESOR MÍNIMO Y CAPA | DB6: BASTONES, ANCLAJE Y CASETONES | DK6: RESPALDO DE UN VOLADO CON b_w PROPIO | DU6: RESULTADO
A7: # | B7: Tablero | C7: Tipo | D7: Destino (lista de DATOS) | E7: a_x — claro en X a ejes | F7: a_y — claro en Y a ejes | G7: Borde inferior (‖ X) | H7: Borde superior (‖ X) | I7: Borde izquierdo (‖ Y) | J7: Borde derecho (‖ Y) | K7: Forzar caso | L7: Colado con los apoyos | M7: SCM — sobrecarga muerta | N7: CV propia (opcional) | O7: Carga en la orilla del volado | P7: L_b — claro de respaldo (volado) | Q7: b_w propio (opcional) | R7: α_fm propio (opcional) | S7: M⁻ del vecino ‖ corto (opcional) | T7: M⁻ del vecino ‖ largo (opcional) | U7: ¿Datos completos? | V7: Borde empotrado (volado) | W7: Claro corto ‖ | X7: a1 corto (volado: largo) | Y7: a2 largo | Z7: m = a1/a2 | AA7: L_n corto | AB7: L_n largo | AC7: b_w nerv. ‖ corto | AD7: Casetón entre nerv. ‖ corto = s − b_w | AE7: b_w cálculo ‖ corto (M⁻ y V) | AF7: b_w cálculo ‖ largo (M⁻) | AG7: Patín b_f ‖ corto | AH7: Patín b_f ‖ largo | AI7: 6.7.8 cumple | AJ7: r inferior | AK7: r superior | AL7: r hasta la malla (al centro de la capa) | AM7: ¿Azotea? | AN7: CV W_m | AO7: PP de diseño | AP7: CM | AQ7: w_u | AR7: Bordes discont. | AS7: … cortos | AT7: Caso automático | AU7: Caso usado | AV7: col. m | AW7: interp. | AX7: M⁻ cont. corto | AY7: M⁻ cont. largo | AZ7: M⁻ disc. corto | BA7: M⁻ disc. largo | BB7: M⁺ corto | BC7: M⁺ largo | BD7: M⁻ extra de los macizos del volado | BE7: V extra de los macizos del volado | BF7: M⁺ corto | BG7: M⁻ corto | BH7: M⁺ largo | BI7: M⁻ largo | BJ7: 3.4.2.1 c) con el vecino | BK7: d para As (var. preferida) | BL7: As req. | BM7: Var. No. | BN7: Pzas | BO7: d real | BP7: M_R | BQ7: Mu/M_R | BR7: ε_t | BS7: d para As (var. preferida) | BT7: As req. | BU7: Var. No. | BV7: Pzas | BW7: d real | BX7: M_R | BY7: Mu/M_R | BZ7: ε_t | CA7: d para As (var. preferida) | CB7: As req. | CC7: Var. No. | CD7: Pzas | CE7: d real | CF7: M_R | CG7: Mu/M_R | CH7: ε_t | CI7: d para As (var. preferida) | CJ7: As req. | CK7: Var. No. | CL7: Pzas | CM7: d real | CN7: M_R | CO7: Mu/M_R | CP7: ε_t | CQ7: V_u por nerv. | CR7: V_cR | CS7: Hileras a macizar | CT7: Estado cortante | CU7: ȳ de la T | CV7: I_T de la T | CW7: h_eq | CX7: α_fm | CY7: h mín. (Tabla 6.7.3.1.2 / volado L/8) | CZ7: Estado peralte | DA7: Capa (diafragma) | DB7: Bastón ‖ corto desde el paño | DC7: Bastón ‖ largo desde el paño | DD7: Bastón también en borde disc. ‖ corto | DE7: Bastón también en borde disc. ‖ largo | DF7: Anclaje en bordes discontinuos | DG7: Casetones ‖ X | DH7: Casetones ‖ Y | DI7: Macizo de orilla X | DJ7: Macizo de orilla Y | DK7: Varillas del volado que siguen en la nervadura de b_w de DATOS (la corrida) | DL7: d de esa nervadura | DM7: M_R de esa nervadura | DN7: V_cR de esa nervadura | DO7: Donde M baja a ese M_R | DP7: Donde V baja a ese V_cR | DQ7: V_u del respaldo junto al apoyo (nerv. ancha) | DR7: Nervadura ancha en el respaldo hasta | DS7: Hileras del respaldo con b_w del volado | DT7: Respaldo del volado | DU7: ARMADO inferior ‖ corto (por nervadura) | DV7: ARMADO superior ‖ corto | DW7: ARMADO inferior ‖ largo | DX7: ARMADO superior ‖ largo | DY7: ESTADO | DZ7: NOTA
A8: cuenta | E8: m | F8: m | G8: CONT./DISC. | H8: CONT./DISC. | I8: CONT./DISC. | J8: CONT./DISC. | K8: AUTO = sale solo | L8: caso I / II | M8: kg/m² | N8: kg/m² | O8: kg/m serv. | P8: m | Q8: cm | R8: — | S8: t·m/nerv. | T8: t·m/nerv. | X8: m | Y8: m | AA8: cm | AB8: cm | AC8: cm | AD8: cm | AE8: cm | AF8: cm | AG8: cm | AH8: cm | AJ8: cm | AK8: cm | AL8: cm | AN8: kg/m² | AO8: kg/m² | AP8: kg/m² | AQ8: kg/m² | AX8: ×10⁻⁴ | AY8: ×10⁻⁴ | AZ8: ×10⁻⁴ | BA8: ×10⁻⁴ | BB8: ×10⁻⁴ | BC8: ×10⁻⁴ | BD8: t·m/nerv. | BE8: t/nerv. | BF8: t·m/nerv. | BG8: t·m/nerv. | BH8: t·m/nerv. | BI8: t·m/nerv. | BK8: cm | BL8: cm² | BO8: cm | BP8: t·m | BQ8: ≤ 1 | BR8: ≥ 0.005 | BS8: cm | BT8: cm² | BW8: cm | BX8: t·m | BY8: ≤ 1 | BZ8: ≥ 0.005 | CA8: cm | CB8: cm² | CE8: cm | CF8: t·m | CG8: ≤ 1 | CH8: ≥ 0.005 | CI8: cm | CJ8: cm² | CM8: cm | CN8: t·m | CO8: ≤ 1 | CP8: ≥ 0.005 | CQ8: t | CR8: t | CS8: por apoyo | CU8: cm | CV8: cm⁴ | CW8: cm | CY8: cm | DB8: cm | DC8: cm | DG8: pzas | DH8: pzas | DI8: cm | DJ8: cm | DK8: pzas | DL8: cm | DM8: t·m | DN8: t | DO8: m desde el paño | DP8: m desde el paño | DQ8: t | DR8: cm desde el paño | DS8: hileras
