Workbook
Name T_BAR: TABLAS!$B$6:$B$14
Name T_DB: TABLAS!$C$6:$C$14
Name T_AB: TABLAS!$D$6:$D$14
Name T_WB: TABLAS!$E$6:$E$14
Name T_MAL: TABLAS!$B$19:$B$22
Name T_MDB: TABLAS!$C$19:$C$22
Name T_MAS: TABLAS!$D$19:$D$22
Name T_MKG: TABLAS!$E$19:$E$22
Name T_FPC: TABLAS!$B$27:$B$31
Name T_FMCI: TABLAS!$C$27:$C$31
Name T_FMCII: TABLAS!$D$27:$D$31
Name T_FPA: TABLAS!$B$35:$B$40
Name T_FMAI: TABLAS!$C$35:$C$40
Name T_FMAII: TABLAS!$D$35:$D$40
Name T_PZ: TABLAS!$B$45:$B$49
Name T_PZMAT: TABLAS!$C$45:$C$49
Name T_PZHUE: TABLAS!$D$45:$D$49
Name T_PZFM2: TABLAS!$E$45:$E$49
Name T_PZVM2: TABLAS!$F$45:$F$49
Name T_SIS: TABLAS!$B$54:$B$57
Name T_SISQ: TABLAS!$C$54:$C$57
Name T_SISSV: TABLAS!$D$54:$D$57
Name T_SISOI: TABLAS!$E$54:$E$57
Name LST_SINO: TABLAS!$B$61:$B$62
Name LST_GRUPO: TABLAS!$C$61:$C$62
Name LST_USO: TABLAS!$D$61:$D$67
Name LST_MORT: TABLAS!$E$61:$E$63
Name LST_FMSRC: TABLAS!$F$61:$F$63
Name LST_VMSRC: TABLAS!$G$61:$G$63
Name LST_FSRC: TABLAS!$B$70:$B$71
Name LST_DIR: TABLAS!$C$70:$C$71
Name LST_POS: TABLAS!$D$70:$D$71
Name LST_VANO: TABLAS!$E$70:$E$71
Name LST_RH: TABLAS!$F$70:$F$73
Name LST_CLASE: TABLAS!$G$70:$G$71
Name LST_MUROS: MUROS!$B$11:$B$70
Name CMB_S: DATOS!$B$111:$B$122
Name CMB_G: DATOS!$C$111:$C$122

Sheet INSTRUCCIONES
B1: REVISIÓN DE MUROS DE MAMPOSTERÍA CONFINADA — NTC 2023 (CDMX)
B3: CÓMO SE USA
B4: 1. DATOS: pieza, mortero, f'm, v'm, concreto, castillo y dala típicos.
B5: 2. MUROS: un renglón por muro (longitud, vanos de izquierda a derecha, viga de apoyo si la hay y fuerzas).
B6: 3. Fuerzas: captúralas en MUROS, o pega la tabla «Pier Forces» de ETABS en PIER_FORCES y en DATOS cambia «Fuerzas de los muros» a ETABS.
B7: 4. DETALLE: escoge un muro y sale su revisión paso a paso. CROQUIS lo dibuja.
B8: 5. RESUMEN: qué cumple, qué no y qué le falta a cada muro. ENTREPISO y DISTORSIONES: revisión global.
B10: COLORES
B11: Amarillo = se captura · Verde = CUMPLE · Ámbar = PENDIENTE (por ejemplo v'm provisional) · Rojo = NO CUMPLE.
B12: En MUROS las columnas de cálculo intermedio están agrupadas: ábrelas con el botón [+] de arriba si quieres ver las cuentas.
B14: NO REVISA
B15: Flexión fuera del plano, muros diafragma, mampostería reforzada interiormente y el diseño de la viga de apoyo (va en la hoja de losas).
... B18: Trae tres muros de ejemplo (M-1 sin vanos, M-2 con puerta y ventana, M-3 sobre una viga) y un entrepiso: escribe encima o bórralos.

Sheet DATOS
B1: DATOS GENERALES — MUROS DE MAMPOSTERÍA CONFINADA, NTC 2023 (CDMX)
B2: Sólo se tocan las celdas amarillas. Valen para todos los muros; lo de cada muro va en MUROS.
B4: 1. PROYECTO Y CLASIFICACIÓN (NTC-Mampostería 1.6)
B5: Concepto | C5: Valor | D5: Unidad | E5: Cómo se calcula / de dónde sale | F5: Referencia
B6: Proyecto | C6: (nombre del proyecto) | D6: — | F6: —
B7: Grupo de la construcción (Reglamento, art. 139) | C7: B | D7: — | E7: A o B | F7: NTC-Criterios 3.4.1 a), p. 7
B8: Superficie construida total | D8: m² | E8: Tipo II: hasta 250 m² | F8: NTC-M 1.6.1 a), p. 15
B9: Niveles (incluye estacionamiento) | D9: — | E9: Tipo II: hasta 2 | F9: NTC-M 1.6.1 b), p. 15
B10: ¿Hay muros estructurales desplantados sobre vigas o sobre la losa? | C10: NO | D10: — | E10: Si hay, es Tipo I | F10: NTC-M 1.6.1 c), p. 15
B11: ¿Hay muros diafragma? | C11: NO | D11: — | F11: NTC-M 1.6.1 d), p. 15
B12: Uso | C12: HABITACIÓN UNIFAMILIAR | D12: — | F12: NTC-M 1.6.1 e), p. 15
B13: Viviendas en el predio (si es plurifamiliar) | D13: — | E13: Plurifamiliar: máximo 10 | F13: NTC-M 1.6.1 f), p. 15
B14: TIPO DE ESTRUCTURA | C14: =IF(AND(ISNUMBER(DATOS!$C$8),ISNUMBER(DATOS!$C$9),DATOS!$C$7="B",DATOS!$C$8<=250,DATOS!$C$9<=2,DATOS!$C$10="NO",COUNTIF(MUROS!$AI$11:$AI$70,"SÍ")=0,DATOS!$C$11="NO",DATOS!$C$12<>"OTRO",OR(DATOS!$C$12<>"HABITACIÓN PLURIFAMILIAR",AND(ISNUMBER(DATOS!$C$13),DATOS!$C$13<=10))),"TIPO II","TIPO I") -> TIPO I | D14: — | E14: Tipo II sólo si cumple todo 1.6.1 | F14: NTC-M 1.6.1 y 1.6.2, p. 15–16
B15: Por qué | C15: =IF(DATOS!$C$14="TIPO II","Cumple a) a f) de 1.6.1",""&IF(OR(NOT(ISNUMBER(DATOS!$C$8)),NOT(ISNUMBER(DATOS!$C$9))),"faltan superficie o niveles; ","")&IF(DATOS!$C$7="A","Grupo A; ","")&IF(DATOS!$C$8>250,"más de 250 m²; ","")&IF(DATOS!$C$9>2,"más de dos niveles; ","")&IF(OR(DATOS!$C$10="SÍ",COUNTIF(MUROS!$AI$11:$AI$70,"SÍ")>0),"muros sobre vigas o losa; ","")&IF(DATOS!$C$11="SÍ","muros diafragma; ","")&IF(DATOS!$C$12="OTRO","uso no listado; ","")&IF(AND(DATOS!$C$12="HABITACIÓN PLURIFAMILIAR",OR(NOT(ISNUMBER(DATOS!$C$13)),DATOS!$C$13>10)),"más de diez viviendas o falta el dato; ","")) -> faltan superficie o niveles; muros sobre vigas o losa; | D15: — | F15: NTC-M 1.6.1, p. 15
B17: 2. MAMPOSTERÍA — PIEZA, MORTERO, f'm Y v'm (NTC-M 2.1, 2.8)
B18: Concepto | C18: Valor | D18: Unidad | E18: Cómo se calcula / de dónde sale | F18: Referencia
B19: Pieza | C19: BLOQUE DE CONCRETO HUECO | D19: — | F19: TABLAS sección E
B20: Material de la pieza | C20: =INDEX(TABLAS!$C$45:$C$49,MATCH(DATOS!$C$19,TABLAS!$B$45:$B$49,0)) -> CONCRETO | D20: — | F20: TABLAS sección E
B21: ¿Pieza hueca? | C21: =INDEX(TABLAS!$D$45:$D$49,MATCH(DATOS!$C$19,TABLAS!$B$45:$B$49,0)) -> SÍ | D21: — | F21: NTC-M Tabla 2.1.1.2, p. 17
B22: f'p — resistencia de diseño a compresión de la pieza | C22: 100 | D22: kg/cm² | E22: De ensayes de las piezas | F22: NTC-M 2.1.2, p. 18
B23: Mortero | C23: I | D23: — | F23: NTC-M 2.5
B24: f_an — área neta / área bruta de la pieza | C24: 0.5 | D24: — | E24: Ficha del fabricante (hueca ≈ 0.5) | F24: NTC-M 6.5.3.3.2, p. 69
B25: h_j — espesor de la junta horizontal | C25: 10 | D25: mm | E25: 10 a 12 mm | F25: NTC-M 4.2.2.2.1, p. 47
B26: Altura de una hilada (pieza + junta) | C26: 20 | D26: cm | E26: Bloque 15×20×40 → 20 cm | F26: NTC-M 6.5.3.2.1, p. 69
B27: f'm de la tabla | C27: =IF(DATOS!$C$23="III",-1,IF(DATOS!$C$20="CONCRETO",IF(DATOS!$C$23="I",IF(DATOS!$C$22<=INDEX(TABLAS!$B$27:$B$31,1),INDEX(TABLAS!$C$27:$C$31,1),IF(DATOS!$C$22>=INDEX(TABLAS!$B$27:$B$31,ROWS(TABLAS!$B$27:$B$31)),INDEX(TABLAS!$C$27:$C$31,ROWS(TABLAS!$B$27:$B$31)),INDEX(TABLAS!$C$27:$C$31,MATCH(DATOS!$C$22,TABLAS!$B$27:$B$31,1))+(INDEX(TABLAS!$C$27:$C$31,MATCH(DATOS!$C$22,TABLAS!$B$27:$B$31,1)+1)-INDEX(TABLAS!$C$27:$C$31,MATCH(DATOS!$C$22,TABLAS!$B$27:$B$31,1)))*(DATOS!$C$22-INDEX(TABLAS!$B$27:$B$31,MATCH(DATOS!$C$22,TABLAS!$B$27:$B$31,1)))/(INDEX(TABLAS!$B$27:$B$31,MATCH(DATOS!$C$22,TABLAS!$B$27:$B$31,1)+1)-INDEX(TABLAS!$B$27:$B$31,MATCH(DATOS!$C$22,TABLAS!$B$27:$B$31,1))))),IF(DATOS!$C$22<=INDEX(TABLAS!$B$27:$B$31,1),INDEX(TABLAS!$D$27:$D$31,1),IF(DATOS!$C$22>=INDEX(TABLAS!$B$27:$B$31,ROWS(TABLAS!$B$27:$B$31)),INDEX(TABLAS!$D$27:$D$31,ROWS(TABLAS!$B$27:$B$31)),INDEX(TABLAS!$D$27:$D$31,MATCH(DATOS!$C$22,TABLAS!$B$27:$B$31,1))+(INDEX(TABLAS!$D$27:$D$31,MATCH(DATOS!$C$22,TABLAS!$B$27:$B$31,1)+1)-INDEX(TABLAS!$D$27:$D$31,MATCH(DATOS!$C$22,TABLAS!$B$27:$B$31,1)))*(DATOS!$C$22-INDEX(TABLAS!$B$27:$B$31,MATCH(DATOS!$C$22,TABLAS!$B$27:$B$31,1)))/(INDEX(TABLAS!$B$27:$B$31,MATCH(DATOS!$C$22,TABLAS!$B$27:$B$31,1)+1)-INDEX(TABLAS!$B$27:$B$31,MATCH(DATOS!$C$22,TABLAS!$B$27:$B$31,1)))))),IF(DATOS!$C$23="I",IF(DATOS!$C$22<=INDEX(TABLAS!$B$35:$B$40,1),INDEX(TABLAS!$C$35:$C$40,1),IF(DATOS!$C$22>=INDEX(TABLAS!$B$35:$B$40,ROWS(TABLAS!$B$35:$B$40)),INDEX(TABLAS!$C$35:$C$40,ROWS(TABLAS!$B$35:$B$40)),INDEX(TABLAS!$C$35:$C$40,MATCH(DATOS!$C$22,TABLAS!$B$35:$B$40,1))+(INDEX(TABLAS!$C$35:$C$40,MATCH(DATOS!$C$22,TABLAS!$B$35:$B$40,1)+1)-INDEX(TABLAS!$C$35:$C$40,MATCH(DATOS!$C$22,TABLAS!$B$35:$B$40,1)))*(DATOS!$C$22-INDEX(TABLAS!$B$35:$B$40,MATCH(DATOS!$C$22,TABLAS!$B$35:$B$40,1)))/(INDEX(TABLAS!$B$35:$B$40,MATCH(DATOS!$C$22,TABLAS!$B$35:$B$40,1)+1)-INDEX(TABLAS!$B$35:$B$40,MATCH(DATOS!$C$22,TABLAS!$B$35:$B$40,1))))),IF(DATOS!$C$22<=INDEX(TABLAS!$B$35:$B$40,1),INDEX(TABLAS!$D$35:$D$40,1),IF(DATOS!$C$22>=INDEX(TABLAS!$B$35:$B$40,ROWS(TABLAS!$B$35:$B$40)),INDEX(TABLAS!$D$35:$D$40,ROWS(TABLAS!$B$35:$B$40)),INDEX(TABLAS!$D$35:$D$40,MATCH(DATOS!$C$22,TABLAS!$B$35:$B$40,1))+(INDEX(TABLAS!$D$35:$D$40,MATCH(DATOS!$C$22,TABLAS!$B$35:$B$40,1)+1)-INDEX(TABLAS!$D$35:$D$40,MATCH(DATOS!$C$22,TABLAS!$B$35:$B$40,1)))*(DATOS!$C$22-INDEX(TABLAS!$B$35:$B$40,MATCH(DATOS!$C$22,TABLAS!$B$35:$B$40,1)))/(INDEX(TABLAS!$B$35:$B$40,MATCH(DATOS!$C$22,TABLAS!$B$35:$B$40,1)+1)-INDEX(TABLAS!$B$35:$B$40,MATCH(DATOS!$C$22,TABLAS!$B$35:$B$40,1)))))))) -> 50 | D27: kg/cm² | E27: Tabla con f'p y el mortero | F27: NTC-M 2.8.1.4, p. 24–25
B28: f'm de ensayes de pilas: f_m medio (corregido por esbeltez) | D28: kg/cm² | E28: Si hay ensayes (9 pilas) | F28: NTC-M 2.8.1.3, p. 23
B29: c_m — coeficiente de variación de las pilas | C29: 0.15 | D29: — | E29: ≥ 0.15 | F29: NTC-M 2.8.1.3.7, p. 24
B30: f'm de ensayes = f_m / (1 + 2.5·c_m) | C30: =IF(ISNUMBER(DATOS!$C$28),DATOS!$C$28/(1+2.5*MAX(DATOS!$C$29,0.15)),0) -> 0 | D30: kg/cm² | F30: NTC-M ec. 2.8.1.3.7, p. 24
B31: f'm Tipo II (sin ensayes) | C31: =INDEX(TABLAS!$E$45:$E$49,MATCH(DATOS!$C$19,TABLAS!$B$45:$B$49,0)) -> 15 | D31: kg/cm² | E31: Sólo Tipo II | F31: NTC-M Tabla 12.2.3.1.2, p. 105
B32: ¿De dónde sale f'm? | C32: TABLA (2.8.1.4) | D32: — | F32: NTC-M 2.8.1, p. 22
B33: f'm — RESISTENCIA DE DISEÑO A COMPRESIÓN QUE SE USA | C33: =IF(DATOS!$C$32="ENSAYES DE PILAS (2.8.1.3)",DATOS!$C$30,IF(DATOS!$C$32="TIPO II (TABLA 12.2.3.1.2)",DATOS!$C$31,MAX(DATOS!$C$27,0))) -> 50 | D33: kg/cm² | F33: NTC-M 2.8.1
B34: ¿El f'm es válido? | C34: =IF(DATOS!$C$33<=0,"NO VÁLIDO: sin f'm (mortero III o faltan ensayes)",IF(DATOS!$C$32="TIPO II (TABLA 12.2.3.1.2)",IF(DATOS!$C$14="TIPO II","VÁLIDO (Tipo II)","NO VÁLIDO: la tabla de Tipo II no aplica a estructura Tipo I"),IF(DATOS!$C$32="ENSAYES DE PILAS (2.8.1.3)","VÁLIDO (ensayes)",IF(OR(DATOS!$C$22<60,AND(DATOS!$C$20="CONCRETO",DATOS!$C$21="NO",DATOS!$C$22<100)),"NO VÁLIDO: f'p fuera de la tabla (2.8.1.4.1)",IF(DATOS!$C$22>IF(DATOS!$C$20="CONCRETO",200,300),"PENDIENTE: f'p arriba de la tabla, se tomó el último renglón","PENDIENTE: confirmar f'p con ensayes de piezas (2.8.1.4.3 d)"))))) -> PENDIENTE: confirmar f'p con ensayes de piezas (2.8.1.4.3 d) | D34: — | F34: NTC-M 2.8.1.4.3, p. 25
B35: v'm de ensayes de muretes: v_m medio | D35: kg/cm² | E35: Si hay ensayes (9 muretes) | F35: NTC-M 2.8.2.4, p. 26
B36: c_v — coeficiente de variación de los muretes | C36: 0.2 | D36: — | E36: ≥ 0.20 | F36: NTC-M 2.8.2.4.6, p. 26
B37: v'm de ensayes = v_m / (1 + 2.5·c_v) | C37: =IF(ISNUMBER(DATOS!$C$35),DATOS!$C$35/(1+2.5*MAX(DATOS!$C$36,0.2)),0) -> 0 | D37: kg/cm² | F37: NTC-M ec. 2.8.2.4.6, p. 26
B38: v'm Tipo II (sin ensayes) | C38: =INDEX(TABLAS!$F$45:$F$49,MATCH(DATOS!$C$19,TABLAS!$B$45:$B$49,0)) -> 2 | D38: kg/cm² | E38: Sólo Tipo II | F38: NTC-M Tabla 12.2.3.2.2, p. 105
B39: v'm provisional (mientras llegan los ensayes) | C39: 2 | D39: kg/cm² | E39: Mientras llegan los ensayes | F39: Criterio provisional — no viene de norma
B40: ¿De dónde sale v'm? | C40: PROVISIONAL (CAPTURA) | D40: — | F40: NTC-M 2.8.2.1, p. 25
B41: v'm — RESISTENCIA DE DISEÑO A COMPRESIÓN DIAGONAL QUE SE USA | C41: =IF(DATOS!$C$40="ENSAYES DE MURETES (2.8.2.4)",DATOS!$C$37,IF(DATOS!$C$40="TIPO II (TABLA 12.2.3.2.2)",DATOS!$C$38,N(DATOS!$C$39))) -> 2 | D41: kg/cm² | F41: NTC-M 2.8.2
B42: ¿El v'm es válido? | C42: =IF(DATOS!$C$41<=0,"NO VÁLIDO: sin v'm",IF(DATOS!$C$40="ENSAYES DE MURETES (2.8.2.4)","VÁLIDO (ensayes)",IF(DATOS!$C$40="TIPO II (TABLA 12.2.3.2.2)",IF(DATOS!$C$14="TIPO II","VÁLIDO (Tipo II)","NO VÁLIDO: estructura Tipo I, el v'm sale de 9 muretes (2.8.2.1)"),"PENDIENTE: v'm provisional; estructura "&DATOS!$C$14&", hacen falta los ensayes de muretes (2.8.2.4)"))) -> PENDIENTE: v'm provisional; estructura TIPO I, hacen falta los ensayes de muretes (2.8.2.4) | D42: — | E42: Tipo I: sólo vale de ensayes | F42: NTC-M 2.8.2.1 y 2.8.2.4.5, p. 25–26
...

Sheet MUROS
B1: MUROS — UN RENGLÓN POR MURO (NTC-MAMPOSTERÍA 2023)
B2: Amarillo = captura. Las cuentas intermedias están agrupadas: ábrelas con [+] arriba de las columnas. DETALLE explica un muro paso a paso y CROQUIS lo dibuja.
B3: ="Proyecto: "&DATOS!$C$6&" · "&DATOS!$C$14&" · f'm = "&TEXT(DATOS!$C$33,"0")&" kg/cm² · v'm = "&TEXT(DATOS!$C$41,"0.00")&" kg/cm² ("&DATOS!$C$40&") · fuerzas: "&DATOS!$C$108&" · castillo "&DATOS!$C$59&"×"&DATOS!$C$60&" con "&DATOS!$C$61&" No. "&DATOS!$C$62 -> Proyecto: (nombre del proyecto) · TIPO I · f'm = 50 kg/cm² · v'm = 2.00 kg/cm² (PROVISIONAL (CAPTURA)) · fuerzas: CAPTURA EN MUROS · castillo 15×15 con 4 No. 3
B5: Muro y Story iguales que en ETABS. H y t vacíos = los de DATOS. | I5: De izquierda a derecha. x = del extremo izquierdo al vano. Puerta: antepecho 0. | AC5: Opcional. Refuerzo horizontal: varilla en juntas o malla. | AI5: Sólo si el muro desplanta sobre una viga (4.1.18). | AQ5: Sólo si DATOS dice CAPTURA. P = la mínima sin factor.
B6: MURO — CAPTURA | I6: VANOS DE IZQUIERDA A DERECHA — CAPTURA | AC6: CASTILLOS EXTREMOS Y REFUERZO HORIZONTAL — CAPTURA | AI6: VIGA DE APOYO — CAPTURA | AQ6: FUERZAS CAPTURADAS (si DATOS dice CAPTURA) | AX6: FUERZAS QUE SALEN DE PIER_FORCES (ETABS) | BI6: FUERZAS DE DISEÑO QUE SE USAN | BS6: SECCIÓN CRÍTICA | CI6: CASTILLOS (6.2) | CO6: COMPRESIÓN (6.4.1) | CR6: FLEXOCOMPRESIÓN EN EL PLANO (6.4.2.2) | CY6: CORTANTE DE LA MAMPOSTERÍA (6.5.2) | DJ6: REFUERZO HORIZONTAL (6.5.3 Y 6.5.4) | EB6: CORTANTE TOTAL | EF6: MURO SOBRE VIGA (4.1.18) | EQ6: CANTIDADES | EU6: RESULTADO
A7: # | B7: Muro (etiqueta del pier en ETABS) | C7: Story de ETABS | D7: Dirección | E7: Posición (para F_E) | F7: L — longitud total | G7: H — altura libre (vacío = DATOS) | H7: t — espesor (vacío = DATOS) | I7: Vano 1 — tipo | J7: Vano 1 — x desde el extremo izquierdo | K7: Vano 1 — ancho | L7: Vano 1 — antepecho (puerta = 0) | M7: Vano 1 — alto del vano | N7: Vano 2 — tipo | O7: Vano 2 — x desde el extremo izquierdo | P7: Vano 2 — ancho | Q7: Vano 2 — antepecho (puerta = 0) | R7: Vano 2 — alto del vano | S7: Vano 3 — tipo | T7: Vano 3 — x desde el extremo izquierdo | U7: Vano 3 — ancho | V7: Vano 3 — antepecho (puerta = 0) | W7: Vano 3 — alto del vano | X7: Vano 4 — tipo | Y7: Vano 4 — x desde el extremo izquierdo | Z7: Vano 4 — ancho | AA7: Vano 4 — antepecho (puerta = 0) | AB7: Vano 4 — alto del vano | AC7: Varillas por castillo extremo (vacío = DATOS) | AD7: No. de varilla del castillo extremo (vacío = DATOS) | AE7: Refuerzo horizontal | AF7: Barras por junta (malla: caras) | AG7: Varilla / alambre / malla (vacío = DATOS) | AH7: Cada cuántas hiladas (varilla) | AI7: ¿Desplanta sobre viga? (4.1.18) | AJ7: Viga | AK7: b de la viga | AL7: h de la viga | AM7: L_v — claro de la viga | AN7: w_u sobre la viga sin el muro | AO7: c — del eje del muro al centro de la viga | AP7: Carga permanente del muro sin factor (vacío = P_u grav./FC) | AQ7: V_u | AR7: M_u (en el plano) | AS7: P mínima SIN factor (para V_mR) | AT7: P_u máxima (compresión) | AU7: P_u mínima factorizada (vacío = P·1.1) | AV7: P_u de gravedad (4.1.18; vacío = P_u máx.) | AW7: V_u de la carga vertical (opcional) | AX7: Story|Muro | AY7: Renglones de sismo | AZ7: Renglones de gravedad | BA7: V_u máx. (sismo) | BB7: M_u máx. (sismo) | BC7: P_u mín. (sismo) | BD7: P_u máx. (sismo) | BE7: P_u máx. (gravedad) | BF7: V_u máx. (gravedad) | BG7: Renglón del V_u máx. | BH7: Combinación y lugar del V_u máx. | BI7: ¿Datos completos? | BJ7: Fuerzas de | BK7: V_u | BL7: M_u | BM7: P mín. sin factor | BN7: P_u mín. | BO7: P_u máx. | BP7: P_u gravedad | BQ7: V_u por carga vertical | BR7: % del V_u por carga vertical | BS7: H usada | BT7: t usado | BU7: Vanos | BV7: Vanos bien capturados | BW7: Tramo 1 en la sección crítica | BX7: Tramo 2 en la sección crítica | BY7: Tramo 3 en la sección crítica | BZ7: Tramo 4 en la sección crítica | CA7: Tramo 5 en la sección crítica | CB7: ΣL de tramos que cuentan (≥ L mín.) | CC7: Tramos que cuentan | CD7: ΣL de todos los tramos | CE7: A_T que cuenta (cortante) | CF7: A_T de todos los tramos | CG7: H/t | CH7: Espesor y esbeltez (6.1.3) | CI7: Separación máx. de castillos | CJ7: Castillos intermedios | CK7: Castillos en el muro | CL7: A_s de un castillo extremo | CM7: ΣA_s de todos los castillos | CN7: H₀ (estribos cerrados) | CO7: F_E | CP7: P_R | CQ7: P_u / P_R | CR7: d' entre castillos extremos | CS7: d | CT7: M₀ = A_s·f_y·d' | CU7: M_R con P_u mín. | CV7: M_R con P_u máx. | CW7: M_R | CX7: M_u / M_R | CY7: f tramo 1 | CZ7: f tramo 2 | DA7: f tramo 3 | DB7: f tramo 4 | DC7: f tramo 5 | DD7: V_mR tramo 1 | DE7: V_mR tramo 2 | DF7: V_mR tramo 3 | DG7: V_mR tramo 4 | DH7: V_mR tramo 5 | DI7: V_mR = Σ tramos | DJ7: A_sh por junta (malla: por cm) | DK7: s_h | DL7: p_h·f_yh | DM7: (p_h·f_yh)e | DN7: η_s | DO7: k₁ | DP7: k₀ tramo 1 | DQ7: k₀ tramo 2 | DR7: k₀ tramo 3 | DS7: k₀ tramo 4 | DT7: k₀ tramo 5 | DU7: V_sR tramo 1 | DV7: V_sR tramo 2 | DW7: V_sR tramo 3 | DX7: V_sR tramo 4 | DY7: V_sR tramo 5 | DZ7: V_sR = Σ tramos | EA7: Refuerzo horizontal (6.5.3 / 6.5.4) | EB7: V_R = V_mR + V_sR | EC7: V_u / V_R | ED7: p_h·f_yh necesario para V_u | EE7: Qué refuerzo horizontal le falta | EF7: I de la viga | EG7: a = L/L_v | EH7: W_p | EI7: f_I | EJ7: K | EK7: k_c | EL7: F_CE | EM7: f_CM | EN7: L_v / h_v | EO7: L_v / h_v máx. por flecha | EP7: Muro sobre viga (4.1.18) | EQ7: Mampostería neta | ER7: Concreto de castillos | ES7: Acero de castillos | ET7: Refuerzo horizontal | EU7: Lo que no cumple | EV7: Pendiente o aviso | EW7: ESTADO | EX7: NOTA
D8: X / Y | F8: m | G8: m | H8: cm | J8: m | K8: m | L8: m | M8: m | O8: m | P8: m | Q8: m | R8: m | T8: m | U8: m | V8: m | W8: m | Y8: m | Z8: m | AA8: m | AB8: m | AC8: pzas | AD8: No. | AF8: pzas | AH8: hiladas | AI8: SÍ / NO | AK8: cm | AL8: cm | AM8: m | AN8: t/m | AO8: m | AP8: t | AQ8: t | AR8: t·m | AS8: t | AT8: t | AU8: t | AV8: t | AW8: t | BA8: t | BB8: t·m | BC8: t | BD8: t | BE8: t | BF8: t | BK8: t | BL8: t·m | BM8: t | BN8: t | BO8: t | BP8: t | BQ8: t | BR8: % | BS8: m | BT8: cm | BW8: m | BX8: m | BY8: m | BZ8: m | CA8: m | CB8: m | CD8: m | CE8: cm² | CF8: cm² | CI8: m | CJ8: pzas | CK8: pzas | CL8: cm² | CM8: cm² | CN8: cm | CP8: t | CQ8: ≤ 1 | CR8: cm | CS8: cm | CT8: t·m | CU8: t·m | CV8: t·m | CW8: t·m | CX8: ≤ 1 | DD8: t | DE8: t | DF8: t | DG8: t | DH8: t | DI8: t | DJ8: cm² | DK8: cm | DL8: kg/cm² | DM8: kg/cm² | DU8: t | DV8: t | DW8: t | DX8: t | DY8: t | DZ8: t | EB8: t | EC8: ≤ 1 | ED8: kg/cm² | EF8: cm⁴ | EH8: kg/cm | EM8: kg/cm² | EN8: ≤ 14 | EQ8: m² | ER8: m³ | ES8: kg | ET8: kg
B9: Ejemplos M-1, M-2 y M-3: escribe encima de las columnas amarillas o bórralos.
A11: =IF(B11="","",ROW()-10) -> 1 | B11: M-1 | C11: N1 | D11: X | E11: EXTREMO | F11: 4 | AE11: NINGUNO | AI11: NO | AQ11: 6 | AR11: 9 | AS11: 7 | AT11: 18 | AX11: =IF(B11="","",C11&"|"&B11) -> N1|M-1 | AY11: =IF(B11="","",COUNTIFS(PIER_FORCES!$O$9:$O$3008,1,PIER_FORCES!$P$9:$P$3008,1)) -> 0 | AZ11: =IF(B11="","",COUNTIFS(PIER_FORCES!$O$9:$O$3008,1,PIER_FORCES!$P$9:$P$3008,2)) -> 0 | BA11: =IF(N(AY11)=0,0,SUMPRODUCT(MAX((PIER_FORCES!$O$9:$O$3008=1)*(PIER_FORCES!$P$9:$P$3008=1)*PIER_FORCES!$R$9:$R$3008))) -> 0 | BB11: =IF(N(AY11)=0,0,SUMPRODUCT(MAX((PIER_FORCES!$O$9:$O$3008=1)*(PIER_FORCES!$P$9:$P$3008=1)*PIER_FORCES!$S$9:$S$3008))) -> 0 | BC11: =IF(N(AY11)=0,0,-SUMPRODUCT(MAX((PIER_FORCES!$O$9:$O$3008=1)*(PIER_FORCES!$P$9:$P$3008=1)*(-PIER_FORCES!$Q$9:$Q$3008)+(1-(PIER_FORCES!$O$9:$O$3008=1)*(PIER_FORCES!$P$9:$P$3008=1))*(-1E9)))) -> 0 | BD11: =IF(N(AY11)=0,0,SUMPRODUCT(MAX((PIER_FORCES!$O$9:$O$3008=1)*(PIER_FORCES!$P$9:$P$3008=1)*PIER_FORCES!$Q$9:$Q$3008+(1-(PIER_FORCES!$O$9:$O$3008=1)*(PIER_FORCES!$P$9:$P$3008=1))*(-1E9)))) -> 0 | BE11: =IF(N(AZ11)=0,BD11,SUMPRODUCT(MAX((PIER_FORCES!$O$9:$O$3008=1)*(PIER_FORCES!$P$9:$P$3008=2)*PIER_FORCES!$Q$9:$Q$3008+(1-(PIER_FORCES!$O$9:$O$3008=1)*(PIER_FORCES!$P$9:$P$3008=2))*(-1E9)))) -> 0 | BF11: =IF(N(AZ11)=0,0,SUMPRODUCT(MAX((PIER_FORCES!$O$9:$O$3008=1)*(PIER_FORCES!$P$9:$P$3008=2)*PIER_FORCES!$R$9:$R$3008))) -> 0 | BG11: =IF(N(AY11)=0,0,SUMPRODUCT(MAX((PIER_FORCES!$O$9:$O$3008=1)*(PIER_FORCES!$P$9:$P$3008=1)*(ABS(PIER_FORCES!$R$9:$R$3008-BA11)<0.000001)*PIER_FORCES!$T$9:$T$3008))) -> 0 | BH11: =IF(N(BG11)=0,"",INDEX(PIER_FORCES!$D$9:$D$3008,BG11)&" "&INDEX(PIER_FORCES!$F$9:$F$3008,BG11)&" / "&INDEX(PIER_FORCES!$G$9:$G$3008,BG11)) | BI11: =IF(B11="","",IF(AND(C11<>"",OR(D11="X",D11="Y"),ISNUMBER(F11),N(F11)>0),"SÍ","NO")) -> SÍ | BJ11: =IF(BI11<>"SÍ","",IF(DATOS!$C$108="ETABS (PIER_FORCES)",IF(N(AY11)>0,"ETABS","NO ESTÁ EN PIER_FORCES"),"CAPTURA")) -> CAPTURA | BK11: =IF(BI11<>"SÍ","",IF(BJ11="ETABS",BA11,IF(BJ11="CAPTURA",N(AQ11),0))) -> 6 | BL11: =IF(BI11<>"SÍ","",IF(BJ11="ETABS",BB11,IF(BJ11="CAPTURA",N(AR11),0))) -> 9 | BM11: =IF(BI11<>"SÍ","",IF(BJ11="ETABS",BC11/DATOS!$C$89,IF(BJ11="CAPTURA",N(AS11),0))) -> 7 | BN11: =IF(BI11<>"SÍ","",IF(BJ11="ETABS",BC11,IF(BJ11="CAPTURA",IF(ISNUMBER(AU11),AU11,N(AS11)*DATOS!$C$89),0))) -> 7.7 | BO11: =IF(BI11<>"SÍ","",IF(BJ11="ETABS",MAX(BD11,BE11),IF(BJ11="CAPTURA",N(AT11),0))) -> 18 | BP11: =IF(BI11<>"SÍ","",IF(BJ11="ETABS",BE11,IF(BJ11="CAPTURA",IF(ISNUMBER(AV11),AV11,N(AT11)),0))) -> 18 | BQ11: =IF(BI11<>"SÍ","",IF(BJ11="ETABS",BF11,IF(BJ11="CAPTURA",N(AW11),0))) -> 0 | BR11: =IF(BI11<>"SÍ","",IF(BK11>0,100*BQ11/BK11,0)) -> 0 | BS11: =IF(BI11<>"SÍ","",IF(ISNUMBER(G11),G11,DATOS!$C$57)) -> 2.5 | BT11: =IF(BI11<>"SÍ","",IF(ISNUMBER(H11),H11,DATOS!$C$58)) -> 15 | BU11: =IF(BI11<>"SÍ","",IF(N(K11)>0,1+IF(N(P11)>0,1+IF(N(U11)>0,1+IF(N(Z11)>0,1,0),0),0),0)) -> 0 | BV11: =IF(BI11<>"SÍ","",IF(AND(OR(BU11<1,AND(N(J11)>=0-0.001,J11+K11<=F11+0.001,N(L11)>=0,N(L11)+N(M11)<=BS11+0.001,N(M11)>0,OR(I11="PUERTA",I11="VENTANA"))),OR(BU11<2,AND(N(O11)>=(J11+K11)-0.001,O11+P11<=F11+0.001,N(Q11)>=0,N(Q11)+N(R11)<=BS11+0.001,N(R11)>0,OR(N11="PUERTA",N11="VENTANA"))),OR(BU11<3,AND(N(T11)>=(O11+P11)-0.001,T11+U11<=F11+0.001,N(V11)>=0,N(V11)+N(W11)<=BS11+0.001,N(W11)>0,OR(S11="PUERTA",S11="VENTANA"))),OR(BU11<4,AND(N(Y11)>=(T11+U11)-0.001,Y11+Z11<=F11+0.001,N(AA11)>=0,N(AA11)+N(AB11)<=BS11+0.001,N(AB11)>0,OR(X11="PUERTA",X11="VENTANA"))),(N(K11)>0)+(N(P11)>0)+(N(U11)>0)+(N(Z11)>0)=BU11),"CUMPLE","REVISAR VANOS: tipo, orden de izquierda a derecha, que quepan en L y en H")) -> CUMPLE | BW11: =IF(BI11<>"SÍ","",MAX(0,IF(BU11>=1,N(J11),F11))) -> 4 | BX11: =IF(BI11<>"SÍ","",MAX(0,IF(BU11>=2,N(O11)-(N(J11)+N(K11)),IF(BU11=1,F11-(N(J11)+N(K11)),0)))) -> 0 | BY11: =IF(BI11<>"SÍ","",MAX(0,IF(BU11>=3,N(T11)-(N(O11)+N(P11)),IF(BU11=2,F11-(N(O11)+N(P11)),0)))) -> 0 | BZ11: =IF(BI11<>"SÍ","",MAX(0,IF(BU11>=4,N(Y11)-(N(T11)+N(U11)),IF(BU11=3,F11-(N(T11)+N(U11)),0)))) -> 0 | CA11: =IF(BI11<>"SÍ","",MAX(0,IF(BU11=4,F11-(N(Y11)+N(Z11)),0))) -> 0 | CB11: =IF(BI11<>"SÍ","",SUMPRODUCT((BW11:CA11>=DATOS!$C$72-0.0001)*BW11:CA11)) -> 4 | CC11: =IF(BI11<>"SÍ","",SUMPRODUCT(--(BW11:CA11>=DATOS!$C$72-0.0001))) -> 1 | CD11: =IF(BI11<>"SÍ","",SUM(BW11:CA11)) -> 4 | CE11: =IF(BI11<>"SÍ","",BT11*CB11*100) -> 6000 | CF11: =IF(BI11<>"SÍ","",BT11*CD11*100) -> 6000 | CG11: =IF(BI11<>"SÍ","",BS11*100/BT11) -> 16.666667 | CH11: =IF(BI11<>"SÍ","",IF(AND(OR(DATOS!$C$14="TIPO II",BT11>=12),CG11<=25),"CUMPLE","NO CUMPLE: "&IF(AND(DATOS!$C$14="TIPO I",BT11<12),"t < 12 cm ","")&IF(CG11>25,"H/t > 25",""))) -> CUMPLE | CI11: =IF(BI11<>"SÍ","",MIN(1.5*BS11,4)) -> 3.75 | CJ11: =IF(BI11<>"SÍ","",SUMPRODUCT((BW11:CA11>=2*DATOS!$C$59/100)*INT((BW11:CA11-DATOS!$C$59/100)/CI11-0.000001)*((BW11:CA11-DATOS!$C$59/100)>0))) -> 1 | CK11: =IF(BI11<>"SÍ","",SUMPRODUCT((BW11:CA11>0.0001)*1+(BW11:CA11>=2*DATOS!$C$59/100)*1)+CJ11) -> 3 | CL11: =IF(BI11<>"SÍ","",IF(ISNUMBER(AC11),AC11,DATOS!$C$61)*INDEX(TABLAS!$D$6:$D$14,MATCH(IF(AD11<>"",AD11,DATOS!$C$62),TABLAS!$B$6:$B$14,0))) -> 2.84 | CM11: =IF(BI11<>"SÍ","",CK11*DATOS!$C$78+IF(CK11>=2,2,CK11)*(CL11-DATOS!$C$78)) -> 8.52 | CN11: =IF(BI11<>"SÍ","",MAX(BS11*100/6,40)) -> 41.666667 | CO11: =IF(BI11<>"SÍ","",IF(CG11<=20,IF(E11="INTERIOR",0.7,0.6),MIN(IF(E11="INTERIOR",0.7,0.6),(1-2/24)*(1-(IF(E11="INTERIOR",0.8,1)*CG11/30)^2)))) -> 0.6 | CP11: =IF(BI11<>"SÍ","",DATOS!$C$87*CO11*(DATOS!$C$33*CF11+CM11*DATOS!$C$48)/1000) -> 120.88224 | CQ11: =IF(BI11<>"SÍ","",IF(CP11>0,BO11/CP11,99)) -> 0.14890525 | CR11: =IF(BI11<>"SÍ","",MAX(0,F11*100-DATOS!$C$59)) -> 385 | CS11: =IF(BI11<>"SÍ","",MAX(0,F11*100-DATOS!$C$59/2)) -> 392.5 | CT11: =IF(BI11<>"SÍ","",CL11*DATOS!$C$48*CR11/100000) -> 45.9228 | CU11: =IF(BI11<>"SÍ","",IF(BN11<0,0.8*CT11*MAX(0,1+BN11/(0.8*CM11*DATOS!$C$48/1000)),IF(BN11<=CP11/3,0.8*CT11+0.3*BN11*CS11/100,(1.5*0.6*CT11+0.15*CP11*CS11/100)*MAX(0,1-BN11/CP11)))) -> 45.80499 | CV11: =IF(BI11<>"SÍ","",IF(BO11<0,0.8*CT11*MAX(0,1+BO11/(0.8*CM11*DATOS!$C$48/1000)),IF(BO11<=CP11/3,0.8*CT11+0.3*BO11*CS11/100,(1.5*0.6*CT11+0.15*CP11*CS11/100)*MAX(0,1-BO11/CP11)))) -> 57.93324 | CW11: =IF(BI11<>"SÍ","",MAX(0,MIN(CU11,CV11))) -> 45.80499 | CX11: =IF(BI11<>"SÍ","",IF(CW11>0,BL11/CW11,IF(BL11>0,99,0))) -> 0.19648514 | CY11: =IF(BI11<>"SÍ","",IF(BW11>0,MAX(1,MIN(1.5,1.5-0.625*(BS11/BW11-0.2))),0)) -> 1.234375 | CZ11: =IF(BI11<>"SÍ","",IF(BX11>0,MAX(1,MIN(1.5,1.5-0.625*(BS11/BX11-0.2))),0)) -> 0 | DA11: =IF(BI11<>"SÍ","",IF(BY11>0,MAX(1,MIN(1.5,1.5-0.625*(BS11/BY11-0.2))),0)) -> 0 | DB11: =IF(BI11<>"SÍ","",IF(BZ11>0,MAX(1,MIN(1.5,1.5-0.625*(BS11/BZ11-0.2))),0)) -> 0 | DC11: =IF(BI11<>"SÍ","",IF(CA11>0,MAX(1,MIN(1.5,1.5-0.625*(BS11/CA11-0.2))),0)) -> 0 | DD11: =IF(BI11<>"SÍ","",IF(OR(BW11<DATOS!$C$72-0.0001,BM11<0,CB11<=0),0,MIN(DATOS!$C$86*(0.5*DATOS!$C$41*BT11*BW11*100+0.3*BM11*BW11/CB11*1000)*CY11,1.5*DATOS!$C$86*DATOS!$C$41*BT11*BW11*100*CY11)/1000)) -> 6.9989063 | DE11: =IF(BI11<>"SÍ","",IF(OR(BX11<DATOS!$C$72-0.0001,BM11<0,CB11<=0),0,MIN(DATOS!$C$86*(0.5*DATOS!$C$41*BT11*BX11*100+0.3*BM11*BX11/CB11*1000)*CZ11,1.5*DATOS!$C$86*DATOS!$C$41*BT11*BX11*100*CZ11)/1000)) -> 0 | DF11: =IF(BI11<>"SÍ","",IF(OR(BY11<DATOS!$C$72-0.0001,BM11<0,CB11<=0),0,MIN(DATOS!$C$86*(0.5*DATOS!$C$41*BT11*BY11*100+0.3*BM11*BY11/CB11*1000)*DA11,1.5*DATOS!$C$86*DATOS!$C$41*BT11*BY11*100*DA11)/1000)) -> 0 | DG11: =IF(BI11<>"SÍ","",IF(OR(BZ11<DATOS!$C$72-0.0001,BM11<0,CB11<=0),0,MIN(DATOS!$C$86*(0.5*DATOS!$C$41*BT11*BZ11*100+0.3*BM11*BZ11/CB11*1000)*DB11,1.5*DATOS!$C$86*DATOS!$C$41*BT11*BZ11*100*DB11)/1000)) -> 0 | DH11: =IF(BI11<>"SÍ","",IF(OR(CA11<DATOS!$C$72-0.0001,BM11<0,CB11<=0),0,MIN(DATOS!$C$86*(0.5*DATOS!$C$41*BT11*CA11*100+0.3*BM11*CA11/CB11*1000)*DC11,1.5*DATOS!$C$86*DATOS!$C$41*BT11*CA11*100*DC11)/1000)) -> 0 | DI11: =IF(BI11<>"SÍ","",SUM(DD11:DH11)) -> 6.9989063 | DJ11: =IF(BI11<>"SÍ","",IF(AE11="VARILLA EN JUNTAS",IF(ISNUMBER(AF11),AF11,2)*INDEX(TABLAS!$D$6:$D$14,MATCH(IF(AG11<>"",AG11,DATOS!$C$73),TABLAS!$B$6:$B$14,0)),IF(AE11="MALLA",IF(ISNUMBER(AF11),AF11,1)*INDEX(TABLAS!$D$19:$D$22,MATCH(IF(AG11<>"",AG11,DATOS!$C$74),TABLAS!$B$19:$B$22,0))/100,IF(AE11="ESCALERILLA",IF(ISNUMBER(AF11),AF11,2)*INDEX(TABLAS!$D$6:$D$14,MATCH(IF(AG11<>"",AG11,DATOS!$C$73),TABLAS!$B$6:$B$14,0)),0)))) -> 0 | DK11: =IF(BI11<>"SÍ","",IF(OR(AE11="VARILLA EN JUNTAS",AE11="ESCALERILLA"),IF(ISNUMBER(AH11),AH11,2)*DATOS!$C$26,IF(AE11="MALLA",1,0))) -> 0 | DL11: =IF(BI11<>"SÍ","",IF(DK11>0,DJ11/(DK11*BT11)*MIN(DATOS!$C$50,IF(AE11="MALLA",5000,6000)),0)) -> 0 | DM11: =IF(BI11<>"SÍ","",IF(AE11="ESCALERILLA",0,MIN(DL11,0.1*DATOS!$C$33*DATOS!$C$24))) -> 0 | DN11: =IF(BI11<>"SÍ","",IF(AE11="MALLA",0.5,IF(DATOS!$C$33<=60,0.55,IF(DATOS!$C$33>=90,0.75,0.55+0.2*(DATOS!$C$33-60)/30)))) -> 0.55 | DO11: =IF(BI11<>"SÍ","",1-DATOS!$C$91*DM11) -> 1 | DP11: =IF(BI11<>"SÍ","",IF(BW11>0,IF(BS11/BW11<=1,1.3,IF(BS11/BW11>=1.5,1,1.3-0.6*(BS11/BW11-1))),0)) -> 1.3 | DQ11: =IF(BI11<>"SÍ","",IF(BX11>0,IF(BS11/BX11<=1,1.3,IF(BS11/BX11>=1.5,1,1.3-0.6*(BS11/BX11-1))),0)) -> 0 | DR11: =IF(BI11<>"SÍ","",IF(BY11>0,IF(BS11/BY11<=1,1.3,IF(BS11/BY11>=1.5,1,1.3-0.6*(BS11/BY11-1))),0)) -> 0 | DS11: =IF(BI11<>"SÍ","",IF(BZ11>0,IF(BS11/BZ11<=1,1.3,IF(BS11/BZ11>=1.5,1,1.3-0.6*(BS11/BZ11-1))),0)) -> 0 | DT11: =IF(BI11<>"SÍ","",IF(CA11>0,IF(BS11/CA11<=1,1.3,IF(BS11/CA11>=1.5,1,1.3-0.6*(BS11/CA11-1))),0)) -> 0 | DU11: =IF(BI11<>"SÍ","",IF(OR(DM11<=0,BW11<DATOS!$C$72-0.0001),0,DATOS!$C$86*MAX(0,IF(BM11>=0,DD11/(DATOS!$C$86*DM11*BT11*BW11*100/1000)*(DP11*DO11-1)+DN11,DO11*DN11))*DM11*BT11*BW11*100/1000)) -> 0 | DV11: =IF(BI11<>"SÍ","",IF(OR(DM11<=0,BX11<DATOS!$C$72-0.0001),0,DATOS!$C$86*MAX(0,IF(BM11>=0,DE11/(DATOS!$C$86*DM11*BT11*BX11*100/1000)*(DQ11*DO11-1)+DN11,DO11*DN11))*DM11*BT11*BX11*100/1000)) -> 0 | DW11: =IF(BI11<>"SÍ","",IF(OR(DM11<=0,BY11<DATOS!$C$72-0.0001),0,DATOS!$C$86*MAX(0,IF(BM11>=0,DF11/(DATOS!$C$86*DM11*BT11*BY11*100/1000)*(DR11*DO11-1)+DN11,DO11*DN11))*DM11*BT11*BY11*100/1000)) -> 0 | DX11: =IF(BI11<>"SÍ","",IF(OR(DM11<=0,BZ11<DATOS!$C$72-0.0001),0,DATOS!$C$86*MAX(0,IF(BM11>=0,DG11/(DATOS!$C$86*DM11*BT11*BZ11*100/1000)*(DS11*DO11-1)+DN11,DO11*DN11))*DM11*BT11*BZ11*100/1000)) -> 0 | DY11: =IF(BI11<>"SÍ","",IF(OR(DM11<=0,CA11<DATOS!$C$72-0.0001),0,DATOS!$C$86*MAX(0,IF(BM11>=0,DH11/(DATOS!$C$86*DM11*BT11*CA11*100/1000)*(DT11*DO11-1)+DN11,DO11*DN11))*DM11*BT11*CA11*100/1000)) -> 0 | DZ11: =IF(BI11<>"SÍ","",SUM(DU11:DY11)) -> 0 | EA11: =IF(BI11<>"SÍ","",IF(OR(AE11="",AE11="NINGUNO"),IF(DATOS!$C$41>=10,"FALTA refuerzo horizontal: v'm ≥ 10 kg/cm² (6.5.2.2)",IF(AND(BM11<0,BK11>0),"FALTA: P en tensión, el refuerzo debe tomar todo el cortante (6.5.1.3)","—")),IF(AE11="ESCALERILLA","NO CUENTA: la escalerilla no se permite para cortante por sismo (6.5.3.1.2)",IF(AE11="MALLA",IF(AND(DL11>=2.5,DL11<=MAX(0.15*DATOS!$C$33*DATOS!$C$24,2.5)),"CUMPLE","NO CUMPLE: "&IF(DL11<2.5,"p_h·f_yh < 2.5 (6.5.4.2.4)","p_h·f_yh > 0.15·f'm·f_an (6.5.4.2.4)")),IF(AND(DK11<=MIN(6*DATOS!$C$26,45),DL11>=3,DL11<=MIN(MAX(0.15*DATOS!$C$33*DATOS!$C$24,3),0.05*DATOS!$C$25/10*MIN(DATOS!$C$50,6000)/DK11),INDEX(TABLAS!$C$6:$C$14,MATCH(IF(AG11<>"",AG11,DATOS!$C$73),TABLAS!$B$6:$B$14,0))>=0.35,INDEX(TABLAS!$C$6:$C$14,MATCH(IF(AG11<>"",AG11,DATOS!$C$73),TABLAS!$B$6:$B$14,0))<=0.75*DATOS!$C$25/10),"CUMPLE","NO CUMPLE: "&IF(DK11>MIN(6*DATOS!$C$26,45),"s_h > 6 hiladas o 45 cm (6.5.3.2.1) ","")&IF(DL11<3,"p_h·f_yh < 3 (6.5.3.3.1) ","")&IF(DL11>MIN(MAX(0.15*DATOS!$C$33*DATOS!$C$24,3),0.05*DATOS!$C$25/10*MIN(DATOS!$C$50,6000)/DK11),"p_h·f_yh > máximo (6.5.3.3.2) ","")&IF(OR(INDEX(TABLAS!$C$6:$C$14,MATCH(IF(AG11<>"",AG11,DATOS!$C$73),TABLAS!$B$6:$B$14,0))<0.35,INDEX(TABLAS!$C$6:$C$14,MATCH(IF(AG11<>"",AG11,DATOS!$C$73),TABLAS!$B$6:$B$14,0))>0.75*DATOS!$C$25/10),"diámetro fuera de 3.5 mm a 0.75·h_j (4.2.2.2.1)","")))))) -> — | EB11: =IF(BI11<>"SÍ","",DI11+DZ11) -> 6.9989063 | EC11: =IF(BI11<>"SÍ","",IF(EB11>0,BK11/EB11,IF(BK11>0,99,0))) -> 0.85727681 | ED11: =IF(BI11<>"SÍ","",IF(CE11<=0,-1,IF(BK11<=DI11,0,IF(IF(BM11>=0,IF((DATOS!$C$86*IF(AE11="MALLA",0.5,IF(DATOS!$C$33<=60,0.55,IF(DATOS!$C$33>=90,0.75,0.55+0.2*(DATOS!$C$33-60)/30)))*CE11/1000-DATOS!$C$91*SUMPRODUCT(DP11:DT11,DD11:DH11))<=0,1E9,(BK11-SUMPRODUCT(DP11:DT11,DD11:DH11))/(DATOS!$C$86*IF(AE11="MALLA",0.5,IF(DATOS!$C$33<=60,0.55,IF(DATOS!$C$33>=90,0.75,0.55+0.2*(DATOS!$C$33-60)/30)))*CE11/1000-DATOS!$C$91*SUMPRODUCT(DP11:DT11,DD11:DH11))),IF((1-4*DATOS!$C$91*BK11*1000/(DATOS!$C$86*IF(AE11="MALLA",0.5,IF(DATOS!$C$33<=60,0.55,IF(DATOS!$C$33>=90,0.75,0.55+0.2*(DATOS!$C$33-60)/30)))*MAX(CE11,1)))<0,1E9,(1-SQRT((1-4*DATOS!$C$91*BK11*1000/(DATOS!$C$86*IF(AE11="MALLA",0.5,IF(DATOS!$C$33<=60,0.55,IF(DATOS!$C$33>=90,0.75,0.55+0.2*(DATOS!$C$33-60)/30)))*MAX(CE11,1)))))/(2*DATOS!$C$91)))>0.1*DATOS!$C$33*DATOS!$C$24+0.000001,-1,MAX(IF(AE11="MALLA",2.5,3),IF(BM11>=0,IF((DATOS!$C$86*IF(AE11="MALLA",0.5,IF(DATOS!$C$33<=60,0.55,IF(DATOS!$C$33>=90,0.75,0.55+0.2*(DATOS!$C$33-60)/30)))*CE11/1000-DATOS!$C$91*SUMPRODUCT(DP11:DT11,DD11:DH11))<=0,1E9,(BK11-SUMPRODUCT(DP11:DT11,DD11:DH11))/(DATOS!$C$86*IF(AE11="MALLA",0.5,IF(DATOS!$C$33<=60,0.55,IF(DATOS!$C$33>=90,0.75,0.55+0.2*(DATOS!$C$33-60)/30)))*CE11/1000-DATOS!$C$91*SUMPRODUCT(DP11:DT11,DD11:DH11))),IF((1-4*DATOS!$C$91*BK11*1000/(DATOS!$C$86*IF(AE11="MALLA",0.5,IF(DATOS!$C$33<=60,0.55,IF(DATOS!$C$33>=90,0.75,0.55+0.2*(DATOS!$C$33-60)/30)))*MAX(CE11,1)))<0,1E9,(1-SQRT((1-4*DATOS!$C$91*BK11*1000/(DATOS!$C$86*IF(AE11="MALLA",0.5,IF(DATOS!$C$33<=60,0.55,IF(DATOS!$C$33>=90,0.75,0.55+0.2*(DATOS!$C$33-60)/30)))*MAX(CE11,1)))))/(2*DATOS!$C$91)))))))) -> 0 | EE11: =IF(BI11<>"SÍ","",IF(ED11=0,"NO REQUIERE: V_mR ≥ V_u",IF(ED11<0,"NO ALCANZA con refuerzo horizontal (haría falta más de 0.1·f'm·f_an efectivo): sube v'm con ensayes, el espesor o la longitud del muro",IF(AND(OR(AE11="VARILLA EN JUNTAS",AE11="MALLA"),LEFT(EA11,6)="CUMPLE",EC11<=1),"YA LO TIENE (pide p_h·f_yh ≥ "&TEXT(ED11,"0.0")&" kg/cm²)","p_h·f_yh ≥ "&TEXT(ED11,"0.0")&" kg/cm² → "&IF(AND(MIN(6,FLOOR(45/DATOS!$C$26,1),FLOOR((2*INDEX(TABLAS!$D$6:$D$14,MATCH("3/16 in",TABLAS!$B$6:$B$14,0)))*MIN(DATOS!$C$50,6000)/(BT11*DATOS!$C$26*MAX(ED11,0.001)),1))>=1,((2*INDEX(TABLAS!$D$6:$D$14,MATCH("3/16 in",TABLAS!$B$6:$B$14,0)))*MIN(DATOS!$C$50,6000)/(MAX(MIN(6,FLOOR(45/DATOS!$C$26,1),FLOOR((2*INDEX(TABLAS!$D$6:$D$14,MATCH("3/16 in",TABLAS!$B$6:$B$14,0)))*MIN(DATOS!$C$50,6000)/(BT11*DATOS!$C$26*MAX(ED11,0.001)),1)),1)*DATOS!$C$26*BT11))<=MIN(MAX(0.15*DATOS!$C$33*DATOS!$C$24,3),0.05*DATOS!$C$25/10*MIN(DATOS!$C$50,6000)/(MIN(6,FLOOR(45/DATOS!$C$26,1),FLOOR((2*INDEX(TABLAS!$D$6:$D$14,MATCH("3/16 in",TABLAS!$B$6:$B$14,0)))*MIN(DATOS!$C$50,6000)/(BT11*DATOS!$C$26*MAX(ED11,0.001)),1))*DATOS!$C$26))),"2 alambres de 3/16"" por junta cada "&MIN(6,FLOOR(45/DATOS!$C$26,1),FLOOR((2*INDEX(TABLAS!$D$6:$D$14,MATCH("3/16 in",TABLAS!$B$6:$B$14,0)))*MIN(DATOS!$C$50,6000)/(BT11*DATOS!$C$26*MAX(ED11,0.001)),1))&" hilada(s) (p_h·f_yh = "&TEXT(((2*INDEX(TABLAS!$D$6:$D$14,MATCH("3/16 in",TABLAS!$B$6:$B$14,0)))*MIN(DATOS!$C$50,6000)/(MAX(MIN(6,FLOOR(45/DATOS!$C$26,1),FLOOR((2*INDEX(TABLAS!$D$6:$D$14,MATCH("3/16 in",TABLAS!$B$6:$B$14,0)))*MIN(DATOS!$C$50,6000)/(BT11*DATOS!$C$26*MAX(ED11,0.001)),1)),1)*DATOS!$C$26*BT11)),"0.00")&")",IF(AND(MIN(6,FLOOR(45/DATOS!$C$26,1),FLOOR((2*INDEX(TABLAS!$D$6:$D$14,MATCH("5/32 in",TABLAS!$B$6:$B$14,0)))*MIN(DATOS!$C$50,6000)/(BT11*DATOS!$C$26*MAX(ED11,0.001)),1))>=1,((2*INDEX(TABLAS!$D$6:$D$14,MATCH("5/32 in",TABLAS!$B$6:$B$14,0)))*MIN(DATOS!$C$50,6000)/(MAX(MIN(6,FLOOR(45/DATOS!$C$26,1),FLOOR((2*INDEX(TABLAS!$D$6:$D$14,MATCH("5/32 in",TABLAS!$B$6:$B$14,0)))*MIN(DATOS!$C$50,6000)/(BT11*DATOS!$C$26*MAX(ED11,0.001)),1)),1)*DATOS!$C$26*BT11))<=MIN(MAX(0.15*DATOS!$C$33*DATOS!$C$24,3),0.05*DATOS!$C$25/10*MIN(DATOS!$C$50,6000)/(MIN(6,FLOOR(45/DATOS!$C$26,1),FLOOR((2*INDEX(TABLAS!$D$6:$D$14,MATCH("5/32 in",TABLAS!$B$6:$B$14,0)))*MIN(DATOS!$C$50,6000)/(BT11*DATOS!$C$26*MAX(ED11,0.001)),1))*DATOS!$C$26))),"2 alambres de 5/32"" por junta cada "&MIN(6,FLOOR(45/DATOS!$C$26,1),FLOOR((2*INDEX(TABLAS!$D$6:$D$14,MATCH("5/32 in",TABLAS!$B$6:$B$14,0)))*MIN(DATOS!$C$50,6000)/(BT11*DATOS!$C$26*MAX(ED11,0.001)),1))&" hilada(s) (p_h·f_yh = "&TEXT(((2*INDEX(TABLAS!$D$6:$D$14,MATCH("5/32 in",TABLAS!$B$6:$B$14,0)))*MIN(DATOS!$C$50,6000)/(MAX(MIN(6,FLOOR(45/DATOS!$C$26,1),FLOOR((2*INDEX(TABLAS!$D$6:$D$14,MATCH("5/32 in",TABLAS!$B$6:$B$14,0)))*MIN(DATOS!$C$50,6000)/(BT11*DATOS!$C$26*MAX(ED11,0.001)),1)),1)*DATOS!$C$26*BT11)),"0.00")&")",IF(AND(MIN(6,FLOOR(45/DATOS!$C$26,1),FLOOR((1*INDEX(TABLAS!$D$6:$D$14,MATCH("3/16 in",TABLAS!$B$6:$B$14,0)))*MIN(DATOS!$C$50,6000)/(BT11*DATOS!$C$26*MAX(ED11,0.001)),1))>=1,((1*INDEX(TABLAS!$D$6:$D$14,MATCH("3/16 in",TABLAS!$B$6:$B$14,0)))*MIN(DATOS!$C$50,6000)/(MAX(MIN(6,FLOOR(45/DATOS!$C$26,1),FLOOR((1*INDEX(TABLAS!$D$6:$D$14,MATCH("3/16 in",TABLAS!$B$6:$B$14,0)))*MIN(DATOS!$C$50,6000)/(BT11*DATOS!$C$26*MAX(ED11,0.001)),1)),1)*DATOS!$C$26*BT11))<=MIN(MAX(0.15*DATOS!$C$33*DATOS!$C$24,3),0.05*DATOS!$C$25/10*MIN(DATOS!$C$50,6000)/(MIN(6,FLOOR(45/DATOS!$C$26,1),FLOOR((1*INDEX(TABLAS!$D$6:$D$14,MATCH("3/16 in",TABLAS!$B$6:$B$14,0)))*MIN(DATOS!$C$50,6000)/(BT11*DATOS!$C$26*MAX(ED11,0.001)),1))*DATOS!$C$26))),"1 alambre de 3/16"" por junta cada "&MIN(6,FLOOR(45/DATOS!$C$26,1),FLOOR((1*INDEX(TABLAS!$D$6:$D$14,MATCH("3/16 in",TABLAS!$B$6:$B$14,0)))*MIN(DATOS!$C$50,6000)/(BT11*DATOS!$C$26*MAX(ED11,0.001)),1))&" hilada(s) (p_h·f_yh = "&TEXT(((1*INDEX(TABLAS!$D$6:$D$14,MATCH("3/16 in",TABLAS!$B$6:$B$14,0)))*MIN(DATOS!$C$50,6000)/(MAX(MIN(6,FLOOR(45/DATOS!$C$26,1),FLOOR((1*INDEX(TABLAS!$D$6:$D$14,MATCH("3/16 in",TABLAS!$B$6:$B$14,0)))*MIN(DATOS!$C$50,6000)/(BT11*DATOS!$C$26*MAX(ED11,0.001)),1)),1)*DATOS!$C$26*BT11)),"0.00")&")",IF(AND(MIN(6,FLOOR(45/DATOS!$C$26,1),FLOOR((1*INDEX(TABLAS!$D$6:$D$14,MATCH("5/32 in",TABLAS!$B$6:$B$14,0)))*MIN(DATOS!$C$50,6000)/(BT11*DATOS!$C$26*MAX(ED11,0.001)),1))>=1,((1*INDEX(TABLAS!$D$6:$D$14,MATCH("5/32 in",TABLAS!$B$6:$B$14,0)))*MIN(DATOS!$C$50,6000)/(MAX(MIN(6,FLOOR(45/DATOS!$C$26,1),FLOOR((1*INDEX(TABLAS!$D$6:$D$14,MATCH("5/32 in",TABLAS!$B$6:$B$14,0)))*MIN(DATOS!$C$50,6000)/(BT11*DATOS!$C$26*MAX(ED11,0.001)),1)),1)*DATOS!$C$26*BT11))<=MIN(MAX(0.15*DATOS!$C$33*DATOS!$C$24,3),0.05*DATOS!$C$25/10*MIN(DATOS!$C$50,6000)/(MIN(6,FLOOR(45/DATOS!$C$26,1),FLOOR((1*INDEX(TABLAS!$D$6:$D$14,MATCH("5/32 in",TABLAS!$B$6:$B$14,0)))*MIN(DATOS!$C$50,6000)/(BT11*DATOS!$C$26*MAX(ED11,0.001)),1))*DATOS!$C$26))),"1 alambre de 5/32"" por junta cada "&MIN(6,FLOOR(45/DATOS!$C$26,1),FLOOR((1*INDEX(TABLAS!$D$6:$D$14,MATCH("5/32 in",TABLAS!$B$6:$B$14,0)))*MIN(DATOS!$C$50,6000)/(BT11*DATOS!$C$26*MAX(ED11,0.001)),1))&" hilada(s) (p_h·f_yh = "&TEXT(((1*INDEX(TABLAS!$D$6:$D$14,MATCH("5/32 in",TABLAS!$B$6:$B$14,0)))*MIN(DATOS!$C$50,6000)/(MAX(MIN(6,FLOOR(45/DATOS!$C$26,1),FLOOR((1*INDEX(TABLAS!$D$6:$D$14,MATCH("5/32 in",TABLAS!$B$6:$B$14,0)))*MIN(DATOS!$C$50,6000)/(BT11*DATOS!$C$26*MAX(ED11,0.001)),1)),1)*DATOS!$C$26*BT11)),"0.00")&")","ninguna combinación de 1 o 2 alambres por junta queda entre el mínimo y el máximo: revisa con malla (6.5.4)")))))))) -> NO REQUIERE: V_mR ≥ V_u | EF11: =IF(BI11<>"SÍ","",IF(AI11="SÍ",N(AK11)*N(AL11)^3/12,0)) -> 0 | EG11: =IF(BI11<>"SÍ","",IF(AND(AI11="SÍ",N(AM11)>0),MIN(1,F11/AM11),0)) -> 0 | EH11: =IF(BI11<>"SÍ","",IF(AI11="SÍ",BP11*1000/(BT11*F11*100)*BT11*(EG11^4-4*EG11^3+8*EG11),0)) -> 0 | EI11: =IF(BI11<>"SÍ","",IF(AND(AI11="SÍ",EH11>0),EH11/(EH11+5*N(AN11)*10),0)) -> 0 | EJ11: =IF(BI11<>"SÍ","",IF(AND(AI11="SÍ",EI11>0,EF11>0),(DATOS!$C$43*BT11*(AM11*100)^3/(DATOS!$C$53*EF11*EI11))^0.25,0)) -> 0 | EK11: =IF(BI11<>"SÍ","",IF(AI11<>"SÍ",0,IF(N(AM11)<=F11,1,IF(MIN(1,N(AO11)/((AM11-F11)/2))<=0.5,0.7+0.6*MIN(1,N(AO11)/((AM11-F11)/2)),1.5-MIN(1,N(AO11)/((AM11-F11)/2)))))) -> 0 | EL11: =IF(BI11<>"SÍ","",IF(AI11<>"SÍ",0,MAX(1,IF(EG11>=1,(1.6*EJ11-3.9),IF(EG11<0.9,((3.2*EJ11-7.8)*EK11),((3.2*EJ11-7.8)*EK11)+((1.6*EJ11-3.9)-((3.2*EJ11-7.8)*EK11))*(EG11-0.9)/0.1))))) -> 0 | EM11: =IF(BI11<>"SÍ","",IF(AI11="SÍ",EL11*BP11*1000/(BT11*F11*100),0)) -> 0 | EN11: =IF(BI11<>"SÍ","",IF(AND(AI11="SÍ",N(AL11)>0),AM11*100/AL11,0)) -> 0 | EO11: =IF(BI11<>"SÍ","",IF(AI11="SÍ",(1/15*DATOS!$C$53*N(AK11)/MAX((IF(ISNUMBER(AP11),AP11,BP11/DATOS!$C$90)*1000/(BT11*F11*100)*BT11*(EG11^4-4*EG11^3+8*EG11))+5*N(AN11)/DATOS!$C$90*10,0.001))^(1/3),0)) -> 0 | EP11: =IF(BI11<>"SÍ","",IF(AI11<>"SÍ","—",IF(OR(N(AK11)<=0,N(AL11)<=0,N(AM11)<=0),"REVISAR: faltan b, h o L_v de la viga",IF(AND(EM11<=DATOS!$C$87*DATOS!$C$33,EN11<=14,N(AL11)>=25,EN11<=EO11),IF(BS11/F11<0.6,"PENDIENTE: H/L < 0.6, falta el análisis de interacción muro–viga (4.1.18.2.1); f_CM es estimado","CUMPLE"),"NO CUMPLE: "&IF(EM11>DATOS!$C$87*DATOS!$C$33,"f_CM > F_R·f'm ","")&IF(EN11>14,"L_v/h_v > 14 ","")&IF(N(AL11)<25,"h_v < 25 cm ","")&IF(EN11>EO11,"flecha (4.1.18.3)",""))))) -> — | EQ11: =IF(BI11<>"SÍ","",MAX(0,F11*BS11-(N(K11)*N(M11)+N(P11)*N(R11)+N(U11)*N(W11)+N(Z11)*N(AB11))-CK11*DATOS!$C$59/100*BS11)) -> 8.875 | ER11: =IF(BI11<>"SÍ","",CK11*DATOS!$C$59*DATOS!$C$60/10000*BS11) -> 0.16875 | ES11: =IF(BI11<>"SÍ","",CK11*(DATOS!$C$61*(BS11+0.6)*INDEX(TABLAS!$E$6:$E$14,MATCH(DATOS!$C$62,TABLAS!$B$6:$B$14,0))+(2*ROUNDUP(CN11/DATOS!$C$65,0)+ROUNDUP(MAX(0,BS11*100-2*CN11)/DATOS!$C$64,0))*((2*(DATOS!$C$60+DATOS!$C$59-4*(DATOS!$C$66-INDEX(TABLAS!$C$6:$C$14,MATCH(DATOS!$C$63,TABLAS!$B$6:$B$14,0))))+15)/100)*INDEX(TABLAS!$E$6:$E$14,MATCH(DATOS!$C$63,TABLAS!$B$6:$B$14,0)))) -> 30.88423 | ET11: =IF(BI11<>"SÍ","",IF(OR(AE11="VARILLA EN JUNTAS",AE11="ESCALERILLA"),INT(BS11*100/MAX(DK11,1))*IF(ISNUMBER(AF11),AF11,2)*CB11*INDEX(TABLAS!$E$6:$E$14,MATCH(IF(AG11<>"",AG11,DATOS!$C$73),TABLAS!$B$6:$B$14,0)),IF(AE11="MALLA",IF(ISNUMBER(AF11),AF11,1)*CB11*BS11*INDEX(TABLAS!$E$19:$E$22,MATCH(IF(AG11<>"",AG11,DATOS!$C$74),TABLAS!$B$19:$B$22,0)),0))) -> 0 | EU11: =IF(BI11<>"SÍ","",""&IF(BJ11="NO ESTÁ EN PIER_FORCES","sin fuerzas en PIER_FORCES; ","")&IF(BV11<>"CUMPLE","vanos; ","")&IF(LEFT(CH11,2)="NO","espesor o esbeltez; ","")&IF(CQ11>1,"compresión; ","")&IF(CX11>1,"flexión; ","")&IF(CB11<=0,"sin tramos de muro (todos son machones menores que L mín.: diséñalos como columnas o baja L mín.); ",IF(EC11>1,"cortante; ",""))&IF(OR(LEFT(EA11,2)="NO",LEFT(EA11,5)="FALTA"),"refuerzo horizontal; ","")&IF(OR(LEFT(EP11,2)="NO",LEFT(EP11,7)="REVISAR"),"muro sobre viga; ","")&IF(LEFT(DATOS!$C$81,2)="NO","castillo típico; ","")&IF(LEFT(DATOS!$C$82,2)="NO","dala típica; ","")&IF(AND(BT11<>DATOS!$C$58,DATOS!$C$60<BT11),"castillo más angosto que el muro; ","")) | EV11: =IF(BI11<>"SÍ","",""&IF(LEFT(EP11,9)="PENDIENTE","análisis muro–viga (H/L < 0.6); ","")&IF(BR11>50,"V_u casi todo por carga vertical; ","")&IF(OR(LEFT(DATOS!$C$42,9)="PENDIENTE",LEFT(DATOS!$C$34,9)="PENDIENTE"),"v'm provisional; ","")&IF(OR(LEFT(DATOS!$C$42,2)="NO",LEFT(DATOS!$C$34,2)="NO"),"f'm o v'm no válido; ","")) -> v'm provisional; | EW11: =IF(BI11<>"SÍ","",IF(EU11<>"","NO CUMPLE: "&LEFT(EU11,LEN(EU11)-2),IF(EV11<>"","CUMPLE — PENDIENTE: "&LEFT(EV11,LEN(EV11)-2),"CUMPLE"))) -> CUMPLE — PENDIENTE: v'm provisional | EX11: Ejemplo: muro sin vanos.
