Workbook

Sheet DATOS
B1: LOSAS NERVADAS CASA ROCHA — DATOS DE ENTRADA
B2: Casa habitación de dos niveles · muros de block de 15 cm confinados con castillos K-15x15 y dalas D-15x20 · losa reticular LR-25 en entrepiso (N+3.00) y azotea (N+6.00). Se diseñan las nervaduras secundarias de cada tablero y las nervaduras principales (dalas que quedan sin muro abajo y trabajan como trabe).
B4: CÓMO SE USA: sólo se tocan las celdas AMARILLAS con número AZUL. Todo lo demás está calculado y se rompe si lo escribes encima. La columna «CÓMO SE CALCULA» dice de dónde sale el número y la columna «REFERENCIA» dice qué documento, norma o archivo lo respalda.
B5: ALCANCE: (1) nervaduras secundarias de 32 tableros con el método de coeficientes de la NTC-Concreto para losas apoyadas en su perímetro; (2) dos tableros en volado (F80012 y F80019); (3) 34 nervaduras principales sin muro abajo diseñadas como trabe, incluida la revisión de muros sobre vigas de la NTC-Mampostería; (4) carga de la losa sobre los muros. NO incluye la escalera, el pergolado de vigas VP-15x40, la revisión de los muros por sismo ni la cimentación.
B6: NORMAS: NTC-Concreto 2023, NTC-Criterios y Acciones 2023 y NTC-Mampostería 2023 (CDMX). Cada fórmula se cotejó contra el texto oficial del compendio NTC 2023 y se cita con su numeral y la página impresa de cada norma (p. ej. «6.7.8.1.4, p. 187»). Los criterios que la norma deja al calculista se marcan como «criterio de esta hoja». ACI 318-19 ya no se usa para nada que la NTC 2023 resuelva.
B8: 1. GEOMETRÍA DE LA LOSA NERVADA LR-25 Y RECUBRIMIENTOS
B9: Casetón de poliestireno 60×60×20, nervadura de 10 cm y capa de 5 cm, como dice la nota 2 del plano de cortes. El E2K lo confirma: sus modificadores de la losa LR-25 salen exactos con esta geometría (ver sección 4).
B10: Concepto | C10: Valor | D10: Unidad | E10: Cómo se calcula / de dónde sale | F10: Referencia
B11: a_c — lado del casetón (separación libre entre nervaduras) | C11: 60 | D11: cm | E11: CAPTURA. Debe ser ≤ 80 cm y ≤ claro/6 para que la losa cuente como encasetonada (se revisa en TABLEROS). | F11: 001_PLANO_CROCHA_R3.0.dxf · NOTAS DE CORTES, nota 2 · NTC-Concreto 2023 (CDMX) 6.7.8.1.4, p. 187
B12: h_c — altura del casetón | C12: 20 | D12: cm | E12: CAPTURA. | F12: 001_PLANO_CROCHA_R3.0.dxf · NOTAS DE CORTES, nota 2
B13: b_w — ancho de la nervadura secundaria | C13: 10 | D13: cm | E13: CAPTURA. Mínimo 10 cm en cualquier punto del peralte. | F13: 001_PLANO_CROCHA_R3.0.dxf · nota 2 · NTC-Concreto 2023 (CDMX) 6.7.8.1.2, p. 187
B14: t — espesor de la capa de compresión | C14: 5 | D14: cm | E14: CAPTURA. Mínimo el mayor de a_c/13 y 5 cm; 6 cm si algún tablero tiene claro ≥ 6 m (diafragma). | F14: 001_PLANO_CROCHA_R3.0.dxf · nota 2 · NTC-Concreto 2023 (CDMX) 6.7.8.3.1, p. 188 y 6.8.3.1.2, p. 189
B15: h — peralte total de la losa | C15: =(DATOS!$C$12+DATOS!$C$14) -> 25 | D15: cm | E15: CALCULADA = h_c + t. Debe dar 25: es la LR-25 del modelo. Máximo 3.5·b_w. | F15: 001_EST_CROCHA_R3.2.e2k · SHELLPROP "LR-25" SLABTHICKNESS 0.25 · NTC-Concreto 2023 (CDMX) 6.7.8.1.3, p. 187
B16: s — separación entre ejes de nervaduras | C16: =(DATOS!$C$11+DATOS!$C$13) -> 70 | D16: cm | E16: CALCULADA = a_c + b_w. Es el ancho tributario de cada nervadura. | F16: Geometría
B17: b_p — ancho de la nervadura principal / dala | C17: 15 | D17: cm | E17: CAPTURA. Es el ancho de las dalas D-15x20 del modelo. En PRINCIPALES cada tramo lleva su propia sección propuesta. | F17: 001_EST_CROCHA_R3.2.e2k · FRAMESECTION "002_D-15x20" B 0.15
B18: ¿Se anotan en planos las precauciones de 3.9.2? (casetón de medida fija que garantiza b_w y silletas que fijan el peralte del lecho superior) | C18: SÍ | D18: — | E18: SELECTOR. b_w = 10 cm < 200 mm y, donde el lecho superior queda con d ≤ 200 mm, la norma pide calcular con 20 mm menos, salvo que se tomen precauciones que garanticen la dimensión y se anoten en planos. Si dices NO, la hoja usa b_w − 2 cm en cortante y en flexión negativa, y d − 2 cm en el lecho superior de cada tablero cuyo d sea ≤ 20 cm. | F18: NTC-Concreto 2023 (CDMX) 3.9.1 d) y e) y 3.9.2, p. 74 · 6.3.1.2 b), p. 117 (las nervaduras son vigas)
B19: b_w de cálculo | C19: =IF(DATOS!$C$18="SÍ",DATOS!$C$13,DATOS!$C$13-2) -> 10 | D19: cm | E19: CALCULADA. | F19: NTC-Concreto 2023 (CDMX) 3.9.1 e), p. 74
B20: r — recubrimiento libre en losa y nervaduras secundarias (interior, A1) | C20: 2 | D20: cm | E20: CAPTURA. El mayor de: 15 mm (colocación en losas), 0.75 × 25 mm = 19 mm (corrosión A1 con f'c = 250) y 20 mm (losas y viguetas no expuestas). Manda 20 mm. | F20: NTC-Concreto 2023 (CDMX) 4.13.1.1 y 4.13.2.2 b), p. 83 · Tabla 4.13.3.1 y 4.13.3.2, p. 84 · Tabla 4.14.16.a, p. 85 · Naim — CASA HABITACIÓN, MEMORIA DE CÁLCULO (sep-2024) pág. 13
B21: r_ext — recubrimiento de caras expuestas a la intemperie (barras ≤ No. 5) | C21: 4 | D21: cm | E21: CAPTURA. Se usa en el lecho inferior de los volados (cara exterior), en su lecho superior si queda a la intemperie (selector de abajo) y en el lecho superior de azotea si la pones como expuesta. Con No. 6 o mayor son 5 cm. | F21: NTC-Concreto 2023 (CDMX) Tabla 4.14.16.a, p. 85 · Tabla 4.3.1, p. 76
B22: r_np — recubrimiento libre de las nervaduras principales que trabajan como trabe | C22: 4 | D22: cm | E22: CAPTURA. Para «vigas» no expuestas la tabla pide 40 mm al estribo (las nervaduras ordinarias son «viguetas» y llevan 20 mm). También lo llevan las nervaduras secundarias de los tableros que no cumplen 6.7.8.1.4: esa losa se diseña como losa apoyada en vigas (6.7.8.1.9) y sus nervaduras ya no son «viguetas». | F22: NTC-Concreto 2023 (CDMX) Tabla 4.14.16.a, p. 85 (vigas: refuerzo principal y estribos, 40 mm) · 6.7.8.1.9 y comentario de 6.7.8, p. 188
B23: ¿La cara superior de la azotea queda expuesta directo a la intemperie? | C23: NO | D23: — | E23: SELECTOR. Con relleno, entortado e impermeabilizante encima la hoja la toma como protegida (criterio del Responsable: la norma no lo dice expresamente). Si dices SÍ, el lecho superior de azotea usa r_ext. | F23: NTC-Concreto 2023 (CDMX) 4.3.2 y Tabla 4.3.1, p. 76 · Tabla 4.14.16.a, p. 85
B24: ¿La cara superior de los volados F80012 y F80019 queda expuesta a la intemperie? | C24: SÍ | D24: — | E24: SELECTOR. Los dos volados del N+3.00 quedan fuera de la azotea (sin techo encima): su cara superior recibe la lluvia directa (exposición A2) y su lecho superior lleva r_ext, igual que la malla. Si dices NO, escribe en planos el criterio de protección del Responsable (piso o impermeabilizante que cubra la losa), como en azotea. | F24: NTC-Concreto 2023 (CDMX) Tabla 4.3.1 c), p. 76 · 4.3.2, p. 76 · Tabla 4.14.16.a, p. 85
B25: No. de estribo en la nervadura secundaria (0 = sin estribo) | C25: 0 | D25: — | E25: CAPTURA. Las nervaduras de 10 cm no llevan estribo: la fuerza cortante la toma el concreto con la ec. 5.5.3.2.1 y donde no alcanza se maciza junto al apoyo. Si algún día se ponen, deben ser de varilla o alambre CORRUGADO (no alambrón liso). | F25: NTC-Concreto 2023 (CDMX) 5.5.3.8.1, p. 97 · Tabla 6.3.5.4.1 c), p. 123 · 2.4.2.1.1, p. 43 y Tabla 2.4.2.2.4.a, p. 46
B26: No. de varilla preferida — lecho INFERIOR de nervaduras secundarias | C26: 4 | D26: — | E26: CAPTURA. Mínimo No. 4: toda nervadura lleva al menos 1 No. 4 abajo y 1 No. 4 arriba, corridas. Si con el máximo de varillas no alcanza, la hoja sube sola al siguiente número. | F26: NTC-Concreto 2023 (CDMX) 6.7.6.1.3, p. 175
B27: No. de varilla preferida — lecho SUPERIOR de nervaduras secundarias | C27: 4 | D27: — | E27: CAPTURA. Misma regla: una varilla del lecho superior es corrida y las demás son bastones. | F27: NTC-Concreto 2023 (CDMX) 6.7.6.1.3, p. 175
B28: Máximo de varillas por lecho en una nervadura de 10 cm | C28: 2 | D28: pzas | E28: CAPTURA. La hoja revisa además que quepan con la separación libre mínima. | F28: Geometría · NTC-Concreto 2023 (CDMX) 14.2.1, p. 347
B29: Mínimo de varillas por lecho y por nervadura | C29: 1 | D29: pzas | E29: CAPTURA. 1 No. 4 corrida. Si As colocada < 4/3 de la requerida, la hoja pide 2 varillas y As mín de viga. | F29: NTC-Concreto 2023 (CDMX) 6.7.6.1.3, p. 175 · 6.3.5.1.1 y 6.3.5.1.3, p. 122
B30: Tamaño máximo del agregado grueso | C30: 1.27 | D30: cm | E30: CAPTURA. 1/2". No más de 2/3 del recubrimiento ni de la separación libre entre barras: con r = 2 cm el máximo es 1.33 cm, así que el de 3/4" NO sirve en esta losa. | F30: NTC-Concreto 2023 (CDMX) 2.2.5.2.1, p. 32
B31: ¿El agregado cabe? (≤ 2/3 de r y de la separación libre) | C31: =IF(DATOS!$C$30<=2/3*MIN(DATOS!$C$20,MAX(2.5,1.5*DATOS!$C$30)),"CUMPLE","NO CUMPLE — usa agregado más chico") -> CUMPLE | D31: — | E31: CALCULADA. | F31: NTC-Concreto 2023 (CDMX) 2.2.5.2.1, p. 32
B32: Separación libre mínima entre varillas | C32: =MAX(2.5,1.5*DATOS!$C$30) -> 2.5 | D32: cm | E32: CALCULADA = el mayor de 25 mm, d_b y 1.5·TMA (d_b se revisa barra por barra). | F32: NTC-Concreto 2023 (CDMX) 14.2.1, p. 347
B33: Ancho libre para varillas dentro de la nervadura secundaria | C33: =DATOS!$C$13-2*DATOS!$C$20-2*IF(DATOS!$C$25=0,0,INDEX(TABLAS!$C$52:$C$58,MATCH(DATOS!$C$25,TABLAS!$B$52:$B$58,0))) -> 6 | D33: cm | E33: CALCULADA = b_w − 2r − 2·estribo con r = 2 cm (tableros que cumplen 6.7.8.1.4). Informativa: TABLEROS revisa renglón por renglón con su r; con r = 4 cm (tableros que no cumplen 6.7.8.1.4 y volados) quedan 2 cm y cabe una sola varilla de d_b ≤ 2 cm. | F33: Geometría
B34: Malla electrosoldada en la capa de compresión | C34: 6x6-6/6 | D34: — | E34: SELECTOR. La lista está en TABLAS. Debe cubrir: contracción y temperatura (0.0018·t), cortante de diafragma (0.0025·t), flexión de la capa con 1 000 kg entre nervaduras, acero mínimo alrededor de la carga concentrada (6.7.6.1.2) y caber con 2 cm de recubrimiento por cara (r_ext = 4 cm donde la cara superior queda expuesta: azotea o volados según los selectores de arriba) (NERVADURA sección 11). Con capa de 5 cm ninguna malla cumple a la vez diafragma, punzonamiento y acero mínimo junto a la carga (RESUMEN, decisión 3). Con capa de 5 cm la 6x6-6/6 es la que mejor cumple; la 6x6-4/4 ya no cabe con su recubrimiento. | F34: NTC-Concreto 2023 (CDMX) 13.8.2.1.1, p. 345 · 6.7.8.1.8, p. 188 · 6.8.6.4, p. 196 · 6.7.6.1.2, p. 175 · Tabla 6.7.4.2.2.3, p. 171 · Tabla 4.14.16.a, p. 85 · Naim — CASA HABITACIÓN, PLANOS EST-01 a EST-06 · EST-03 (dice 6x6-10/10)
B35: Ø del alambre de la malla | C35: =INDEX(TABLAS!$C$63:$C$66,MATCH(DATOS!$C$34,TABLAS!$B$63:$B$66,0))/10 -> 0.488 | D35: cm | E35: CALCULADA. La malla va con r = 2 cm a la cara superior y las varillas superiores de las nervaduras pasan DEBAJO de ella: su d pierde 2·Ø. | F35: TABLAS sección C
B37: 2. MATERIALES
B38: Concepto | C38: Valor | D38: Unidad | E38: Cómo se calcula / de dónde sale | F38: Referencia
B39: f'c — resistencia del concreto | C39: 250 | D39: kg/cm² | E39: CAPTURA. Concreto Clase 1A (250 ≤ f'c < 400). Es también el mínimo para estructuras de ductilidad baja y para exposición A1, A2 y B1. | F39: 001_EST_CROCHA_R3.2.e2k · MATERIAL "Concreto f'c=250kg/cm2. Clase 1A" · NTC-Concreto 2023 (CDMX) 2.2.2 a), p. 30 · Tabla 2.2.6.3, p. 33 · 4.4.1.1 y 4.5.2 a), p. 78
B40: fy — fluencia de la varilla corrugada | C40: 4200 | D40: kg/cm² | E40: CAPTURA. Grado 42, NMX-B-506. Es también el máximo para estribos. | F40: 001_EST_CROCHA_R3.2.e2k · MATERIAL "Fy=4200" · NTC-Concreto 2023 (CDMX) Tabla 2.4.2.1.2.a, p. 43 y Tabla 2.4.2.2.4.a, p. 46
B41: fy de la malla electrosoldada | C41: 5000 | D41: kg/cm² | E41: CAPTURA. Alambre de malla NMX-B-290; en contracción, temperatura y flexión de losas se permite hasta 7 000. En 2023 la cuantía de temperatura ya no depende de fy. | F41: NTC-Concreto 2023 (CDMX) 2.4.2.1.6 y 2.4.2.1.7, p. 44 · Tabla 2.4.2.2.4.a renglón «Otras», p. 46 · plano EST Casa Yépez (Naim), nota 1.2
B42: fy de los estribos de nervaduras principales | C42: 4200 | D42: kg/cm² | E42: CAPTURA. Varilla corrugada; para cortante el máximo es 4 200. | F42: NTC-Concreto 2023 (CDMX) 5.5.2.4.3, p. 94 · Tabla 2.4.2.2.4.a, p. 46
B43: γc — peso volumétrico del concreto reforzado | C43: 2.44 | D43: t/m³ | E43: CAPTURA. El mismo del modelo (valor máximo probable). | F43: 001_EST_CROCHA_R3.2.e2k · WEIGHTPERVOLUME 2440 · NTC-Criterios y Acciones 2023 (CDMX) 5.1.1.2, p. 9
...

Sheet APOYOS
B1: APOYOS — DÓNDE SE APOYA CADA TABLERO, CUÁLES SON LAS NERVADURAS PRINCIPALES Y DÓNDE HAY VACÍOS
B2: Se cruzó el modelo (muros, castillos y dalas por nivel) con el plano arquitectónico (capa 004_Vacios y escalera) y con el DXF de áreas tributarias. Los muros que cargan la losa N+3.00 son los de planta baja; los que cargan la azotea N+6.00 son los del primer nivel.
B4: A. LO QUE SE ENCONTRÓ
B5: 1) AZOTEA (N+6.00): casi todos los bordes caen sobre muros del primer nivel. Sólo 4 tramos cortos quedan sin muro (bordes de los tragaluces, la ventana del área de tendido y el borde del vacío de la escalera) y todos llegan a muros en sus dos extremos.
B6: 2) ENTREPISO (N+3.00): en planta baja sólo hay muros en los ejes A y J y en dos núcleos (baño junto a la cochera y servicios atrás). La cochera mide 8.70 m libres y la sala tiene el vacío de doble altura: muchas dalas del modelo quedan sin muro abajo y en realidad son NERVADURAS PRINCIPALES que trabajan como trabe.
B7: 3) En el modelo tal cual, varias de esas principales rematan en nudos que no tienen nada abajo: las esquinas de la cochera (x = 4.327 y = 1.919; x = 5.923 y = 2.921), las esquinas del vacío (x = 4.327 con y = 7.871 y 14.021), la esquina de la escalera (F-8) y la esquina C-10. Así quedan en volado de 4 a 8 m: con 25 cm de peralte NO funcionan.
B8: 4) En esos mismos nudos el primer nivel SÍ tiene castillo, pero no baja a planta baja (31 castillos sin continuidad, lista F). La propuesta de esta hoja es bajar 7 de ellos a cimentación y agregar uno nuevo en la llegada de la escalera (lista B). Con eso todas las principales quedan apoyadas en sus dos extremos.
B9: 5) F80012 (área de tendido, fuera del eje A) y F80019 (terraza entre los ejes 14 y 15) son VOLADOS de 2.00 m. Sus orillas libres llevan nervadura de borde, no trabe. La de F80019 recibe el barandal de 333.7 kg/m que trae el modelo.
B10: 6) VACÍOS: doble altura de la sala (4.17 × 6.00 m), cubo de la escalera curva, vacío sobre la escalera en azotea y tres tragaluces de 0.30 m en azotea. F80028 y F80029 son prácticamente hueco (quedan 0.60 y 0.53 m² de losa): se tratan como marco de hueco, no como tablero.
B11: 7) En azotea, F80032 y F80010 están en el modelo como «Slab1» (maciza de 20 cm, concreto 4000 psi), no como LR-25. El plano dice losa reticular: aquí se diseñan como LR-25 y conviene corregirlos en ETABS.
B12: 8) F2 (azotea, sobre la terraza del frente) no tiene cargas en el modelo. Aquí se le pone la misma sobrecarga que al tablero vecino F80023 (270 kg/m²): REVISAR.
B14: B. CASTILLOS QUE SE PROPONE BAJAR A CIMENTACIÓN — TÚ DECIDES
B15: Si pones NO, los tramos que dependen de ese castillo pasan a volado en PRINCIPALES y la hoja te dice si así aguantan. OJO: si rechazas un castillo que parte un tramo en dos (C2, C4), junta a mano los dos renglones de PRINCIPALES en uno solo con el claro completo.
B16: Castillo | C16: ¿Se acepta? | D16: x (m) | E16: y (m) | F16: Ejes | G16: Tramos que dependen | H16: Por qué
B17: C1 — PROPUESTO | C17: SÍ | D17: 4.327 | E17: 1.919 | F17: x=4.327-2 | G17: NP-01, NP-20 | H17: Esquina libre al frente de la cochera: ahí rematan las nervaduras de y = 1.919 y de x = 4.327. Ya hay castillo en el primer nivel.
B18: C2 — PROPUESTO | C18: SÍ | D18: 4.327 | E18: 2.921 | F18: x=4.327-3 | G18: NP-02, NP-03, NP-20, NP-21 | H18: Cochera: cruce de x = 4.327 con y = 2.921, bajo esquina de muro del primer nivel. Ya hay castillo en el primer nivel.
B19: C3 — PROPUESTO | C19: SÍ | D19: 5.923 | E19: 2.921 | F19: G-3 | G19: NP-03, NP-29 | H19: Esquina libre de la cochera (lado pickup): ahí rematan y = 2.921 y el eje G. Ya hay castillo en el primer nivel.
B20: C4 — PROPUESTO | C20: SÍ | D20: 4.327 | E20: 7.871 | F20: x=4.327-7 | G20: NP-06, NP-22, NP-23 | H20: Esquina sur del vacío de doble altura: recibe la nervadura del eje 7. Ya hay castillo en el primer nivel.
B21: C5 — PROPUESTO | C21: SÍ | D21: 4.327 | E21: 14.021 | F21: x=4.327-y=14.021 | G21: NP-10, NP-23 | H21: Esquina norte del vacío de doble altura: sin él x = 4.327 queda en volado de 8 m. Ya hay castillo en el primer nivel.
B22: C6 — PROPUESTO | C22: SÍ | D22: 5.422 | E22: 9.95 | F22: F-8 | G22: NP-08, NP-26 | H22: Esquina escalera/cocina (F-8): recibe la nervadura del eje F que carga muro de planta alta. Ya hay castillo en el primer nivel.
B23: C7 — PROPUESTO | C23: SÍ | D23: 5.441 | E23: 8.91 | F23: F-y=8.910 | G23: NP-07, NP-25 | H23: Llegada de la escalera: amarra el anillo x = 5.44 / y = 8.91. NO hay castillo arriba: es propuesta nueva, revisar con arquitectura.
B24: C8 — PROPUESTO | C24: SÍ | D24: 3.427 | E24: 15.846 | F24: C-y=15.846 | G24: NP-12, NP-19 | H24: Esquina C-10 (arq.): ahí remata y = 15.846 que carga muro de planta alta. Ya hay castillo en el primer nivel.
B26: C. BORDES DE CADA TABLERO — APOYO Y CONTINUIDAD
B27: «Apoyo» dice qué hay bajo el borde: MURO, una NERVADURA PRINCIPAL (ver PRINCIPALES) o nada (LIBRE). «Continuidad» dice si del otro lado sigue losa: con eso TABLEROS escoge el caso de la tabla de coeficientes. La continuidad es AMARILLA: la puedes cambiar si el criterio automático no te convence.
B28: Tablero | C28: Lado | D28: Largo (m) | E28: % sobre muro | F28: Apoyo | G28: Continuidad | H28: Del otro lado | I28: Vacío o hueco junto
B29: F80001 N+3.00 | C29: inferior | D29: 4.327 | E29: 0.005 | F29: NERV. PRINCIPAL NP-01 | G29: DISCONTINUO
B30: F80001 N+3.00 | C30: superior | D30: 4.327 | E30: 0.005 | F30: NERV. PRINCIPAL NP-02 | G30: CONTINUO | H30: F80003
B31: F80001 N+3.00 | C31: izquierdo | D31: 1.002 | E31: 1 | F31: MURO | G31: DISCONTINUO
B32: F80001 N+3.00 | C32: derecho | D32: 1.002 | E32: 0 | F32: NERV. PRINCIPAL NP-20 | G32: DISCONTINUO
B33: F80003 N+3.00 | C33: inferior | D33: 4.327 | E33: 0.005 | F33: NERV. PRINCIPAL NP-02 | G33: CONTINUO | H33: F80001
B34: F80003 N+3.00 | C34: superior | D34: 4.327 | E34: 0.333 | F34: MURO | G34: CONTINUO | H34: F80005, F80006
B35: F80003 N+3.00 | C35: izquierdo | D35: 3.025 | E35: 1 | F35: MURO | G35: DISCONTINUO | H35: F80005
B36: F80003 N+3.00 | C36: derecho | D36: 3.025 | E36: 0.007 | F36: NERV. PRINCIPAL NP-21 | G36: CONTINUO | H36: F80004
B37: F80004 N+3.00 | C37: inferior | D37: 1.596 | E37: 0 | F37: NERV. PRINCIPAL NP-03 | G37: DISCONTINUO
B38: F80004 N+3.00 | C38: superior | D38: 1.596 | E38: 1 | F38: MURO | G38: CONTINUO | H38: F80008
B39: F80004 N+3.00 | C39: izquierdo | D39: 3.025 | E39: 0.007 | F39: NERV. PRINCIPAL NP-21 | G39: CONTINUO | H39: F80003
B40: F80004 N+3.00 | C40: derecho | D40: 3.025 | E40: 0.007 | F40: NERV. PRINCIPAL NP-29 | G40: DISCONTINUO
B41: F80005 N+3.00 | C41: inferior | D41: 2.925 | E41: 1 | F41: MURO | G41: CONTINUO | H41: F80003
B42: F80005 N+3.00 | C42: superior | D42: 2.925 | E42: 1 | F42: MURO | G42: CONTINUO | H42: F80007
B43: F80005 N+3.00 | C43: izquierdo | D43: 1.602 | E43: 1 | F43: MURO | G43: DISCONTINUO
...

Sheet CARGAS
B1: CARGAS — PESO PROPIO, SOBRECARGA, CARGA VIVA Y CARGAS LINEALES
B2: La sobrecarga de cada tablero se toma del modelo (varía de 160 a 315 kg/m²) y vive en TABLEROS. Aquí está el desglose de referencia de Naim, los incrementos de la NTC y las cargas lineales del modelo.
B4: 1. PESO PROPIO DE LA LOSA NERVADA
B5: Concepto | C5: Valor | D5: Unidad | E5: Cómo se calcula / de dónde sale | F5: Referencia
B6: Peso propio geométrico LR-25 (con casetón) | C6: =DATOS!$C$70 -> 253.67347 | D6: kg/m² | E6: Enlazado a DATOS sección 4. | F6: DATOS
B7: Incremento por losa colada en el lugar | C7: =DATOS!$C$95 -> 20 | D7: kg/m² | E7: DATOS sección 5. | F7: NTC-Criterios y Acciones 2023 (CDMX) 5.1.2.1, p. 9
B8: Incremento por capa de mortero | C8: =DATOS!$C$96 -> 20 | D8: kg/m² | E8: DATOS sección 5. No se aplica donde la carga muerta es favorable (p. ej. el claro que equilibra un volado). | F8: NTC-Criterios y Acciones 2023 (CDMX) 5.1.2.1 y 5.1.2.2, p. 9
B9: Peso propio de diseño | C9: =DATOS!$C$70+DATOS!$C$95+DATOS!$C$96 -> 293.67347 | D9: kg/m² | E9: Suma de los tres renglones. Es el que usa TABLEROS. | F9: NTC-Criterios y Acciones 2023 (CDMX) 5.1.2.1, p. 9
B10: Peso propio que trae el modelo | C10: =DATOS!$C$71 -> 251.427 | D10: kg/m² | E10: Enlazado a DATOS sección 4. | F10: 001_EST_CROCHA_R3.2.e2k
B12: 2. SOBRECARGA MUERTA — DESGLOSE DE REFERENCIA (NAIM)
B13: Sólo de referencia: no entra en ningún cálculo. Sirve para juzgar si las sobrecargas del modelo (columna SCM de TABLEROS) son razonables. Ojo: la «carga adicional 0.04 t/m²» de Naim es el mismo incremento de 40 kg/m² de 5.1.2.1.
B14: Concepto | C14: Carga | D14: Unidad | E14: Cómo se obtiene | F14: Referencia
B15: Entrepiso — relleno 8 cm | C15: 0.13 | D15: t/m² | E15: 1.60 t/m³ × 0.08 m | F15: Naim — CASA HABITACIÓN, MEMORIA DE CÁLCULO (sep-2024) · pág. 5, CARGAS DE ENTREPISO
B16: Entrepiso — piso 3 cm | C16: 0.06 | D16: t/m² | E16: 2.00 t/m³ × 0.03 m | F16: Naim — CASA HABITACIÓN, MEMORIA DE CÁLCULO (sep-2024) · pág. 5, CARGAS DE ENTREPISO
B17: Entrepiso — pegapiso 3 cm | C17: 0.05 | D17: t/m² | E17: 1.50 t/m³ × 0.03 m | F17: Naim — CASA HABITACIÓN, MEMORIA DE CÁLCULO (sep-2024) · pág. 5, CARGAS DE ENTREPISO
B18: Entrepiso — yeso 3 cm | C18: 0.05 | D18: t/m² | E18: 1.50 t/m³ × 0.03 m | F18: Naim — CASA HABITACIÓN, MEMORIA DE CÁLCULO (sep-2024) · pág. 5, CARGAS DE ENTREPISO
B19: Entrepiso — instalaciones | C19: 0.02 | D19: t/m² | E19: — | F19: Naim — CASA HABITACIÓN, MEMORIA DE CÁLCULO (sep-2024) · pág. 5, CARGAS DE ENTREPISO
B20: Entrepiso — carga adicional | C20: 0.04 | D20: t/m² | E20: — | F20: Naim — CASA HABITACIÓN, MEMORIA DE CÁLCULO (sep-2024) · pág. 5, CARGAS DE ENTREPISO
B21: Entrepiso — TOTAL según Naim | C21: 0.33 | D21: t/m² | E21: Naim reporta 0.33 (subtotal 0.29 + carga adicional 0.04); la suma de los renglones de arriba da 0.35 (0.338 sin redondear). | F21: Naim — CASA HABITACIÓN, MEMORIA DE CÁLCULO (sep-2024) · pág. 5
B22: Azotea — relleno 10 cm | C22: 0.16 | D22: t/m² | E22: 1.60 t/m³ × 0.10 m | F22: Naim — CASA HABITACIÓN, MEMORIA DE CÁLCULO (sep-2024) · pág. 5, CARGAS DE AZOTEA
B23: Azotea — yeso 3 cm | C23: 0.05 | D23: t/m² | E23: 1.50 t/m³ × 0.03 m | F23: Naim — CASA HABITACIÓN, MEMORIA DE CÁLCULO (sep-2024) · pág. 5, CARGAS DE AZOTEA
B24: Azotea — impermeabilizante | C24: 0.03 | D24: t/m² | E24: 1.40 t/m³ × 0.02 m | F24: Naim — CASA HABITACIÓN, MEMORIA DE CÁLCULO (sep-2024) · pág. 5, CARGAS DE AZOTEA
B25: Azotea — instalaciones | C25: 0.02 | D25: t/m² | E25: — | F25: Naim — CASA HABITACIÓN, MEMORIA DE CÁLCULO (sep-2024) · pág. 5, CARGAS DE AZOTEA
B26: Azotea — carga adicional | C26: 0.04 | D26: t/m² | E26: — | F26: Naim — CASA HABITACIÓN, MEMORIA DE CÁLCULO (sep-2024) · pág. 5, CARGAS DE AZOTEA
B27: Azotea — TOTAL según Naim | C27: 0.29 | D27: t/m² | E27: Naim reporta 0.29 (la suma de renglones da 0.30). | F27: Naim — CASA HABITACIÓN, MEMORIA DE CÁLCULO (sep-2024) · pág. 5
B28: Sobrecarga del modelo — mínima y máxima en entrepiso | C28: =TEXT(MIN(TABLEROS!$T$9:$T$28),"0")&" a "&TEXT(MAX(TABLEROS!$T$9:$T$28),"0") -> 160 a 270 | D28: kg/m² | E28: Rango de la columna SCM de TABLEROS para N+3.00. | F28: 001_EST_CROCHA_R3.2.e2k · AREALOAD "Sobrecarga"
B29: Sobrecarga del modelo — mínima y máxima en azotea | C29: =TEXT(MIN(TABLEROS!$T$29:$T$40),"0")&" a "&TEXT(MAX(TABLEROS!$T$29:$T$40),"0") -> 270 a 315 | D29: kg/m² | E29: Rango de la columna SCM de TABLEROS para N+6.00. | F29: 001_EST_CROCHA_R3.2.e2k · AREALOAD "Sobrecarga"
B31: 3. COMBINACIONES DE DISEÑO
B32: Concepto | C32: Valor | D32: Unidad | E32: Cómo se calcula / de dónde sale | F32: Referencia
B33: Carga muerta CM = PP de diseño + SCM | C33: por tablero | D33: — | E33: TABLEROS, columna CM. | F33: NTC-Criterios y Acciones 2023 (CDMX) 5.1.2.1, p. 9
B34: w_u gravitacional = 1.3·CM + 1.5·W_m | C34: por tablero | D34: — | E34: TABLEROS, columna w_u. Grupo B. W_m uniforme en todos los tableros a la vez: se permite porque W_m ≤ 0.75·CM. | F34: NTC-Criterios y Acciones 2023 (CDMX) 2.3.1 a), p. 5 y 3.4.1 a), p. 7 · NTC-Concreto 2023 (CDMX) 3.3.2.2.3, p. 50
B35: w_u con granizo (sólo azotea) = 1.1·(CM + W_g) | C35: =DATOS!$C$57*(CARGAS!$C$9+270+DATOS!$C$97) -> 743.79082 | D35: kg/m² | E35: Ejemplo con SCM = 270 kg/m². En TABLEROS se toma el mayor de las dos combinaciones; en azotea manda la gravitacional. | F35: NTC-Criterios y Acciones 2023 (CDMX) 3.4.1 b), p. 7 · 7.3.1.1 y 7.3.1.3, p. 17
B36: w de servicio = CM + W_m | C36: por tablero | D36: — | E36: TABLEROS, columna w serv. Factor de carga 1.0. | F36: NTC-Criterios y Acciones 2023 (CDMX) 3.3.2, p. 6 y 3.4.1 d), p. 7
B37: Carga sostenida para flechas diferidas = CM + W | C37: por tramo | D37: — | E37: PRINCIPALES, revisión de flechas. | F37: NTC-Criterios y Acciones 2023 (CDMX) 6.1.2.1 c), p. 10
B39: 4. CARGAS CONCENTRADAS QUE PIDE LA NORMA
B40: Concepto | C40: Valor | D40: Unidad | E40: Cómo se calcula / de dónde sale | F40: Referencia
B41: Capa entre nervaduras: carga concentrada mínima | C41: 1000 | D41: kg | E41: En un área de 10 × 10 cm en la posición más desfavorable. Se revisa en NERVADURA sección 11 (flexión, punzonamiento y acero mínimo de la capa). | F41: NTC-Concreto 2023 (CDMX) 6.7.8.1.6, p. 187 · 6.7.8.1.8, p. 188
B42: Habitación: carga en lugar de W_m cuando sea más desfavorable | C42: 500 | D42: kg | E42: En 50 × 50 cm. La cubre la revisión de 1 000 kg en 10 × 10 cm. | F42: NTC-Criterios y Acciones 2023 (CDMX) Tabla 6.1.2.2 nota [1], p. 11
B43: Azotea: carga concentrada en la posición más crítica | C43: 100 | D43: kg | E43: La cubre la revisión de 1 000 kg. Tinacos y equipos van aparte y deben indicarse en planos. | F43: NTC-Criterios y Acciones 2023 (CDMX) Tabla 6.1.2.2 notas [7] y [8], p. 12
B44: Carga transitoria al colar la azotea sobre el entrepiso | C44: 150 | D44: kg/m² | E44: Más el peso del colado y la cimbra, y 150 kg concentrados. Indicar en planos el apuntalamiento a planta baja mientras se cuela N+6.00. | F44: NTC-Criterios y Acciones 2023 (CDMX) 6.1.3.1, p. 10
...

Sheet TABLEROS
B1: TABLEROS — NERVADURAS SECUNDARIAS DE CADA TABLERO (MÉTODO DE COEFICIENTES, NTC-CONCRETO 2023 TABLA 3.4.2.1)
B2: Un renglón por tablero. Momentos = coeficiente × 10⁻⁴ × w_u × a1² por metro; por nervadura × s. Abajo trabaja la sección T con el patín efectivo de la Tabla 5.2.1.4.2; arriba sólo la nervadura (b_w de cálculo). Toda nervadura lleva al menos 1 No. 4 corrida abajo y 1 No. 4 corrida arriba (6.7.6.1.3); arriba, las demás varillas son bastones. Lo AMARILLO se puede cambiar. El detalle paso a paso está en NERVADURA.
B3: ESTADO: «CUMPLE» = flexión, ε_t ≥ 0.005, cortante, peralte, capa y apoyos bien. «VER PRINCIPALES» = el tablero pasa pero alguna nervadura principal que lo recibe no. «MACIZAR n hilera(s)» = quitar casetones junto al apoyo por cortante. «6.7.8: NO» = la separación libre a_c pasa de 1/6 del claro corto (6.7.8.1.4): la losa se diseña como losa apoyada en vigas (6.7.8.1.9): nervaduras con recubrimiento de viga (r_np) y sin el ×1.1 de V_cR. «3.4.2.1 c)» = los M⁻ del borde común con un vecino difieren más de 50 % del menor: los coeficientes quedan fuera de su campo y conviene confirmar con el modelo; aun así se distribuye 2/3 del desequilibrio (3.4.3.1).
B6: TABLERO | F6: GEOMETRÍA | T6: CARGAS (kg/m²) | Z6: CASO DE LA TABLA | AF6: COEFICIENTES ×10⁻⁴ (Tabla 3.4.2.1, interpolados en m) | AN6: DISTRIBUCIÓN CON LOS VECINOS (3.4.3.1) Y 3.4.2.1 c) | BA6: MOMENTOS POR NERVADURA (t·m) | BF6: INFERIOR — CLARO CORTO | BN6: SUPERIOR — CLARO CORTO | BV6: INFERIOR — CLARO LARGO | CD6: SUPERIOR — CLARO LARGO | CL6: CORTANTE | CP6: PERALTE Y CAPA | CU6: DETALLE Y RESUMEN
B7: Tablero | C7: Nivel | D7: Modo | E7: Destino | F7: Lx | G7: Ly | H7: a_x usado | I7: a_y usado | J7: a1 corto | K7: a2 largo | L7: m = a1/a2 | M7: Corto ‖ | N7: Claro libre corto | O7: Claro libre largo | P7: Patín b_f corto | Q7: Patín b_f largo | R7: r inferior | S7: r superior | T7: SCM | U7: CV W_m | V7: PP diseño | W7: CM | X7: w serv. | Y7: w_u | Z7: Bordes discont. | AA7: … cortos | AB7: … largos | AC7: Caso automático | AD7: Forzar caso | AE7: Caso usado | AF7: col. m | AG7: interp. | AH7: M⁻ cont. corto | AI7: M⁻ cont. largo | AJ7: M⁻ disc. corto | AK7: M⁻ disc. largo | AL7: M⁺ corto | AM7: M⁺ largo | AN7: M⁻ borde inferior por nerv. | AO7: M⁻ borde superior por nerv. | AP7: M⁻ borde izquierdo por nerv. | AQ7: M⁻ borde derecho por nerv. | AR7: Rigidez d³/a1 ‖X | AS7: Rigidez d³/a1 ‖Y | AT7: M⁻ corto que deja el vecino | AU7: M⁻ largo que deja el vecino | AV7: ΔM⁺ corto por distribución | AW7: ΔM⁺ largo por distribución | AX7: ΔV por volado vecino | AY7: Vecinos con M⁻ > 50 % distinto | AZ7: 3.4.2.1 c) | BA7: Carga en orilla de volado | BB7: M⁺ corto | BC7: M⁻ corto | BD7: M⁺ largo | BE7: M⁻ largo | BF7: d para As (var. preferida) | BG7: As req. | BH7: Var. No. | BI7: Pzas | BJ7: d | BK7: M_R | BL7: Mu/M_R | BM7: ε_t | BN7: d para As (var. preferida) | BO7: As req. | BP7: Var. No. | BQ7: Pzas | BR7: d | BS7: M_R | BT7: Mu/M_R | BU7: ε_t | BV7: d para As (var. preferida) | BW7: As req. | BX7: Var. No. | BY7: Pzas | BZ7: d | CA7: M_R | CB7: Mu/M_R | CC7: ε_t | CD7: d para As (var. preferida) | CE7: As req. | CF7: Var. No. | CG7: Pzas | CH7: d | CI7: M_R | CJ7: Mu/M_R | CK7: ε_t | CL7: 6.7.8 cumple | CM7: V_u por nerv. | CN7: V_cR | CO7: Estado | CP7: α_fm | CQ7: h mín. Tabla 6.7.3.1.2 / volado L/8 | CR7: h_eq / h | CS7: Estado | CT7: Capa (diafragma) | CU7: Bastón ‖ corto desde paño | CV7: Bastón ‖ largo desde paño | CW7: Casetones ‖X | CX7: Casetones ‖Y | CY7: Apoyos | CZ7: ESTADO | DA7: Nota
F8: m | G8: m | H8: m | I8: m | J8: m | K8: m | N8: cm | O8: cm | P8: cm | Q8: cm | R8: cm | S8: cm | T8: kg/m² | U8: kg/m² | V8: kg/m² | W8: kg/m² | X8: kg/m² | Y8: kg/m² | AN8: t·m | AO8: t·m | AP8: t·m | AQ8: t·m | AR8: cm² | AS8: cm² | AT8: t·m | AU8: t·m | AV8: t·m | AW8: t·m | AX8: t | BA8: kg/m (serv.) | BB8: t·m | BC8: t·m | BD8: t·m | BE8: t·m | BF8: cm | BG8: cm² | BJ8: cm | BK8: t·m | BM8: ≥ 0.005 | BN8: cm | BO8: cm² | BR8: cm | BS8: t·m | BU8: ≥ 0.005 | BV8: cm | BW8: cm² | BZ8: cm | CA8: t·m | CC8: ≥ 0.005 | CD8: cm | CE8: cm² | CH8: cm | CI8: t·m | CK8: ≥ 0.005 | CM8: t | CN8: t | CQ8: cm | CR8: cm | CU8: cm | CV8: cm
